Workbook
Name Testing_status: #REF!
Name Testing_status: #REF!
Name Testing_status: #REF!
Name Testing_status: #REF!
Name Testing_status: #REF!
Name Display_Week: #REF!
Name Project_Start: #REF!

Sheet Cover
B6: ECP
B7: TESTCASE
F9: Mã hiệu
F10: Phiên bản | I10: 1.0
F11: Ngày hiệu lực

Sheet Revision history
C1: REVISION HISTORY - TESTCASE
B4: Phiên bản testcase (Testcase version) | C4: Ngày cập nhật (Date Update) | D4: Người tạo (Author) | E4: Người xem xét (Reviewer) | F4: Tên chức năng (Function name) | G4: Mô tả chức năng (Function description) | H4: Tình trạng (Status)
B5: v1.0
B6: v1.0_Sprint 10 | C6: 20/03/2026 | D6: GiangDC2, AnhDC4 | E6: HuyenNHK | F6: Luồng checkout Net,Combo net | G6: Luồng checkout Net,Combo net | H6: Thêm mới
B7: v1.0 Sprint 12 | C7: 46026 | D7: GiangDC2, AnhDC4 | E7: HuyenNHK | F7: Thông tin chung | G7: Các TC dùng chung cho tất cả dịch vụ (UI, navigation, form validation cơ bản...) | H7: Thêm mới
F8: FPL SA | G8: Luồng checkout FPL SA | H8: Thêm mới
F9: Ultra Fast | G9: Luồng checkout Ultra Fast | H9: Thêm mới
F10: Hyper Fast | G10: Luồng checkout Hyper Fast | H10: Thêm mới
F11: Chi tiết các dịch vụ SA | G11: Chi tiết các dịch vụ SA(FPTPlay, UltraFast, HyperFast) | H11: Thêm mới
F12: Trang tổng hợp dịch vụ | G12: Trang tổng hợp dịch vụ số (UltraFast, HyperFast) | H12: Thêm mới
B13: v1.1
B14: v1.1 sprint 2 | D14: GiangDC2, AnhDC4 | E14: HuyenNHK | F14: Quản lý nội dung gói bán | G14: giangdc2 update
F15: Quản lý gói bán
F16: Quản lý đặc tính | G16: giangdc2 update
F17: Chi tiết thiết bị | G17: Chi tiết thiết bị: AP, Smart Home, Smart Tivi, Camera
C29: REVISION HISTORY - TEMPLATE
B30: [Phần này chỉ giành cho QA update]
B32: Ngày hiệu lực | C32: Version | D32: Người tạo | E32: Người xem xét | F32: Người phê duyệt | G32: Nội dung thay đổi
C33: 1.0 | G33: Tạo mới

Sheet Guideline
B3: QUY ĐỊNH CHUNG
B4: 1. Tên File Testcase/Report đặt theo chuẩn:
B5: ISC_[Tên Dự Án]_[Version Dự Án]_TC_[Version File TC theo Revision history]_R[Số vòng test khi report].xlsx
B6: ISC_[Tên Dự Án]_[Version Dự Án]_Report.xlsx
B7: VD: ISC_Salary FTI_V2.2_TC_V1.0_R1.xlsx ISC_Salary FTI_V2.2_Report.xlsx
B8: 2. Khi update nội dung File Testcase (Add/Update/Delete các Function/Screen) phải tăng [Version File TC] và quản lý lịch sử thay đổi trong Revision history.
B9: 3. Các Function/ Screen khác nhau được tách ra thành từng sheet.
B10: - [Nội Dung Test/Test Title] trongTestcase tách ra từng case riêng biệt không gộp lại thành 1 case nhưng kết quả test khác nhau.
B11: - [Người thực hiện]: sử dụng tên email, chỉ duy nhất một người thực hiện.
B13: BẢNG PHÂN LOẠI TRẠNG THÁI TESTCASE
B15: Trạng thái | C15: Ý nghĩa
B16: (Blank) | C16: Trạng thái mặc định khi chưa thực hiện test
B17: Pass | C17: Thực hiện thành công case
B18: Fail | C18: Không thành công case, có lỗi phát sinh
B19: Block | C19: Case này không thể thực hiện/Pending, ghi rõ lý do trong phần ghi chú: (VD: Do chưa dev xong, Không có điều kiện - dữ liệu test, Tài liệu đặc tả sai, Đã thay đổi yêu cầu...).
B20: N/A | C20: - Case Suggest - Case Won't fix
B23: BẢNG PHÂN LOẠI ĐỘ ƯU TIÊN
B25: Trạng thái | C25: Ý nghĩa
B26: High | C26: - Phải thực hiện trong bất kỳ vòng nào - Case ảnh hưởng trực tiếp đến nhiều người dùng - Chức năng, nghiệp vụ
B27: Medium | C27: - Phải thực hiện ít nhất một lần - Ảnh hưởng đến người dùng
B28: Low | C28: - Có thể bỏ qua khi rút ngắn thời gian test - Case không gây ảnh hưởng nhiều đến người dùng - Case phụ thêm - Không quy định trong tài liệu

Sheet Summary
D1: SUMMARY
A5: Project name | C5: ECP | D5: Version | E5: V1.0 - Sprint 12
A6: Division | C6: ECOM | D6: Project Manager - PM | E6: TaiTT13
B8: STT | C8: Mã chức năng | D8: Sheet Name | E8: Function/ Screen | F8: Số Testcase | G8: Round 1 (09/04/2026 - 15/04/2026) | K8: G:I | L8: Round 2 (dd/mm/yyyy - dd/mm/yyyy) | P8: K:K | Q8: Round 3(dd/mm/yyyy - dd/mm/yyyy) | U8: O:O | V8: Round 4 (dd/mm/yyyy - dd/mm/yyyy) | Z8: S:S | AA8: Round 5 (dd/mm/yyyy - dd/mm/yyyy) | AE8: W:W | AF8: Round 6 (dd/mm/yyyy - dd/mm/yyyy) | AJ8: AA:AA | AK8: Round 7 (dd/mm/yyyy - dd/mm/yyyy) | AO8: AE:AE | AP8: Round 8 (dd/mm/yyyy - dd/mm/yyyy) | AT8: AI:AI | AU8: Round 9 (dd/mm/yyyy - dd/mm/yyyy) | AY8: AM:AM | AZ8: Round 10 (dd/mm/yyyy - dd/mm/yyyy) | BD8: AQ:AQ
G9: Excute Testcase | H9: Pass | I9: Fail | J9: N/A | K9: Block | L9: Excute Testcase | M9: Pass | N9: Fail | O9: N/A | P9: Block | Q9: Excute Testcase | R9: Pass | S9: Fail | T9: N/A | U9: Block | V9: Excute Testcase | W9: Pass | X9: Fail | Y9: N/A | Z9: Block | AA9: Excute Testcase | AB9: Pass | AC9: Fail | AD9: N/A | AE9: Block | AF9: Excute Testcase | AG9: Pass | AH9: Fail | AI9: N/A | AJ9: Block | AK9: Excute Testcase | AL9: Pass | AM9: Fail | AN9: N/A | AO9: Block | AP9: v | AQ9: Pass | AR9: Fail | AS9: N/A | AT9: Block | AU9: Excute Testcase | AV9: Pass | AW9: Fail | AX9: N/A | AY9: Block | AZ9: Excute Testcase | BA9: Pass | BB9: Fail | BC9: N/A | BD9: Block
B10: 1 | C10: TC_01 | D10: Thông tin chung | E10: Thông tin chung | F10: 300 | G10: =SUM(H10:J10) -> 0 | H10: =COUNTIF(INDIRECT("'"&$D10&"'!"&K$8),"Pass") -> 0 | I10: =COUNTIF(INDIRECT("'"&$D10&"'!"&K$8),"Fail") -> 0 | J10: =COUNTIF(INDIRECT("'"&$D10&"'!"&K$8),"N/A") -> 0 | K10: =COUNTIF(INDIRECT("'"&$D10&"'!"&K$8),"Block") -> 0 | L10: =SUM(M10:O10) -> 0 | M10: =COUNTIF(INDIRECT("'"&$D10&"'!"&P$8),"Pass") -> 0 | N10: =COUNTIF(INDIRECT("'"&$D10&"'!"&P$8),"Fail") -> 0 | O10: =COUNTIF(INDIRECT("'"&$D10&"'!"&P$8),"N/A") -> 0 | P10: =COUNTIF(INDIRECT("'"&$D10&"'!"&P$8),"Block") -> 0 | Q10: =SUM(R10:T10) -> 0 | R10: =COUNTIF(INDIRECT("'"&$D10&"'!"&U$8),"Pass") -> 0 | S10: =COUNTIF(INDIRECT("'"&$D10&"'!"&U$8),"Fail") -> 0 | T10: =COUNTIF(INDIRECT("'"&$D10&"'!"&U$8),"N/A") -> 0 | U10: =COUNTIF(INDIRECT("'"&$D10&"'!"&U$8),"Block") -> 0 | V10: =SUM(W10:Y10) -> 0 | W10: =COUNTIF(INDIRECT("'"&$D10&"'!"&Z$8),"Pass") -> 0 | X10: =COUNTIF(INDIRECT("'"&$D10&"'!"&Z$8),"Fail") -> 0 | Y10: =COUNTIF(INDIRECT("'"&$D10&"'!"&Z$8),"N/A") -> 0 | Z10: =COUNTIF(INDIRECT("'"&$D10&"'!"&Z$8),"Block") -> 0 | AA10: =SUM(AB10:AD10) -> 0 | AB10: =COUNTIF(INDIRECT("'"&$D10&"'!"&AE$8),"Pass") -> 0 | AC10: =COUNTIF(INDIRECT("'"&$D10&"'!"&AE$8),"Fail") -> 0 | AD10: =COUNTIF(INDIRECT("'"&$D10&"'!"&AE$8),"N/A") -> 0 | AE10: =COUNTIF(INDIRECT("'"&$D10&"'!"&AE$8),"Block") -> 0 | AF10: =SUM(AG10:AI10) -> 0 | AG10: =COUNTIF(INDIRECT("'"&$D10&"'!"&AJ$8),"Pass") -> 0 | AH10: =COUNTIF(INDIRECT("'"&$D10&"'!"&AJ$8),"Fail") -> 0 | AI10: =COUNTIF(INDIRECT("'"&$D10&"'!"&AJ$8),"N/A") -> 0 | AJ10: =COUNTIF(INDIRECT("'"&$D10&"'!"&AJ$8),"Block") -> 0 | AK10: =SUM(AL10:AN10) -> 0 | AL10: =COUNTIF(INDIRECT("'"&$D10&"'!"&AO$8),"Pass") -> 0 | AM10: =COUNTIF(INDIRECT("'"&$D10&"'!"&AO$8),"Fail") -> 0 | AN10: =COUNTIF(INDIRECT("'"&$D10&"'!"&AO$8),"N/A") -> 0 | AO10: =COUNTIF(INDIRECT("'"&$D10&"'!"&AO$8),"Block") -> 0 | AP10: =SUM(AQ10:AS10) -> 0 | AQ10: =COUNTIF(INDIRECT("'"&$D10&"'!"&AT$8),"Pass") -> 0 | AR10: =COUNTIF(INDIRECT("'"&$D10&"'!"&AT$8),"Fail") -> 0 | AS10: =COUNTIF(INDIRECT("'"&$D10&"'!"&AT$8),"N/A") -> 0 | AT10: =COUNTIF(INDIRECT("'"&$D10&"'!"&AT$8),"Block") -> 0 | AU10: =SUM(AV10:AX10) -> 0 | AV10: =COUNTIF(INDIRECT("'"&$D10&"'!"&AY$8),"Pass") -> 0 | AW10: =COUNTIF(INDIRECT("'"&$D10&"'!"&AY$8),"Fail") -> 0 | AX10: =COUNTIF(INDIRECT("'"&$D10&"'!"&AY$8),"N/A") -> 0 | AY10: =COUNTIF(INDIRECT("'"&$D10&"'!"&AY$8),"Block") -> 0 | AZ10: =SUM(BA10:BC10) -> 0 | BA10: =COUNTIF(INDIRECT("'"&$D10&"'!"&BD$8),"Pass") -> 0 | BB10: =COUNTIF(INDIRECT("'"&$D10&"'!"&BD$8),"Fail") -> 0 | BC10: =COUNTIF(INDIRECT("'"&$D10&"'!"&BD$8),"N/A") -> 0 | BD10: =COUNTIF(INDIRECT("'"&$D10&"'!"&BD$8),"Block") -> 0
B11: 2 | C11: TC_02 | D11: FPL SA | E11: FPL SA | F11: =COUNTIF(INDIRECT("'"&D11&"'!A:A"),C11&"*") -> 0 | G11: =SUM(H11:J11) -> 0 | H11: =COUNTIF(INDIRECT("'"&$D11&"'!"&K$8),"Pass") -> 0 | I11: =COUNTIF(INDIRECT("'"&$D11&"'!"&K$8),"Fail") -> 0 | J11: =COUNTIF(INDIRECT("'"&$D11&"'!"&K$8),"N/A") -> 0 | K11: =COUNTIF(INDIRECT("'"&$D11&"'!"&K$8),"Block") -> 0 | L11: =SUM(M11:O11) -> 0 | M11: =COUNTIF(INDIRECT("'"&$D11&"'!"&P$8),"Pass") -> 0 | N11: =COUNTIF(INDIRECT("'"&$D11&"'!"&P$8),"Fail") -> 0 | O11: =COUNTIF(INDIRECT("'"&$D11&"'!"&P$8),"N/A") -> 0 | P11: =COUNTIF(INDIRECT("'"&$D11&"'!"&P$8),"Block") -> 0 | Q11: =SUM(R11:T11) -> 0 | R11: =COUNTIF(INDIRECT("'"&$D11&"'!"&U$8),"Pass") -> 0 | S11: =COUNTIF(INDIRECT("'"&$D11&"'!"&U$8),"Fail") -> 0 | T11: =COUNTIF(INDIRECT("'"&$D11&"'!"&U$8),"N/A") -> 0 | U11: =COUNTIF(INDIRECT("'"&$D11&"'!"&U$8),"Block") -> 0 | V11: =SUM(W11:Y11) -> 0 | W11: =COUNTIF(INDIRECT("'"&$D11&"'!"&Z$8),"Pass") -> 0 | X11: =COUNTIF(INDIRECT("'"&$D11&"'!"&Z$8),"Fail") -> 0 | Y11: =COUNTIF(INDIRECT("'"&$D11&"'!"&Z$8),"N/A") -> 0 | Z11: =COUNTIF(INDIRECT("'"&$D11&"'!"&Z$8),"Block") -> 0 | AA11: =SUM(AB11:AD11) -> 0 | AB11: =COUNTIF(INDIRECT("'"&$D11&"'!"&AE$8),"Pass") -> 0 | AC11: =COUNTIF(INDIRECT("'"&$D11&"'!"&AE$8),"Fail") -> 0 | AD11: =COUNTIF(INDIRECT("'"&$D11&"'!"&AE$8),"N/A") -> 0 | AE11: =COUNTIF(INDIRECT("'"&$D11&"'!"&AE$8),"Block") -> 0 | AF11: =SUM(AG11:AI11) -> 0 | AG11: =COUNTIF(INDIRECT("'"&$D11&"'!"&AJ$8),"Pass") -> 0 | AH11: =COUNTIF(INDIRECT("'"&$D11&"'!"&AJ$8),"Fail") -> 0 | AI11: =COUNTIF(INDIRECT("'"&$D11&"'!"&AJ$8),"N/A") -> 0 | AJ11: =COUNTIF(INDIRECT("'"&$D11&"'!"&AJ$8),"Block") -> 0 | AK11: =SUM(AL11:AN11) -> 0 | AL11: =COUNTIF(INDIRECT("'"&$D11&"'!"&AO$8),"Pass") -> 0 | AM11: =COUNTIF(INDIRECT("'"&$D11&"'!"&AO$8),"Fail") -> 0 | AN11: =COUNTIF(INDIRECT("'"&$D11&"'!"&AO$8),"N/A") -> 0 | AO11: =COUNTIF(INDIRECT("'"&$D11&"'!"&AO$8),"Block") -> 0 | AP11: =SUM(AQ11:AS11) -> 0 | AQ11: =COUNTIF(INDIRECT("'"&$D11&"'!"&AT$8),"Pass") -> 0 | AR11: =COUNTIF(INDIRECT("'"&$D11&"'!"&AT$8),"Fail") -> 0 | AS11: =COUNTIF(INDIRECT("'"&$D11&"'!"&AT$8),"N/A") -> 0 | AT11: =COUNTIF(INDIRECT("'"&$D11&"'!"&AT$8),"Block") -> 0 | AU11: =SUM(AV11:AX11) -> 0 | AV11: =COUNTIF(INDIRECT("'"&$D11&"'!"&AY$8),"Pass") -> 0 | AW11: =COUNTIF(INDIRECT("'"&$D11&"'!"&AY$8),"Fail") -> 0 | AX11: =COUNTIF(INDIRECT("'"&$D11&"'!"&AY$8),"N/A") -> 0 | AY11: =COUNTIF(INDIRECT("'"&$D11&"'!"&AY$8),"Block") -> 0 | AZ11: =SUM(BA11:BC11) -> 0 | BA11: =COUNTIF(INDIRECT("'"&$D11&"'!"&BD$8),"Pass") -> 0 | BB11: =COUNTIF(INDIRECT("'"&$D11&"'!"&BD$8),"Fail") -> 0 | BC11: =COUNTIF(INDIRECT("'"&$D11&"'!"&BD$8),"N/A") -> 0 | BD11: =COUNTIF(INDIRECT("'"&$D11&"'!"&BD$8),"Block") -> 0
B12: 3 | C12: TC_03 | D12: Ultra Fast | E12: Ultra Fast | F12: =COUNTIF(INDIRECT("'"&D12&"'!A:A"),C12&"*") -> 0 | G12: =SUM(H12:J12) -> 0 | H12: =COUNTIF(INDIRECT("'"&$D12&"'!"&K$8),"Pass") -> 0 | I12: =COUNTIF(INDIRECT("'"&$D12&"'!"&K$8),"Fail") -> 0 | J12: =COUNTIF(INDIRECT("'"&$D12&"'!"&K$8),"N/A") -> 0 | K12: =COUNTIF(INDIRECT("'"&$D12&"'!"&K$8),"Block") -> 0 | L12: =SUM(M12:O12) -> 0 | M12: =COUNTIF(INDIRECT("'"&$D12&"'!"&P$8),"Pass") -> 0 | N12: =COUNTIF(INDIRECT("'"&$D12&"'!"&P$8),"Fail") -> 0 | O12: =COUNTIF(INDIRECT("'"&$D12&"'!"&P$8),"N/A") -> 0 | P12: =COUNTIF(INDIRECT("'"&$D12&"'!"&P$8),"Block") -> 0 | Q12: =SUM(R12:T12) -> 0 | R12: =COUNTIF(INDIRECT("'"&$D12&"'!"&U$8),"Pass") -> 0 | S12: =COUNTIF(INDIRECT("'"&$D12&"'!"&U$8),"Fail") -> 0 | T12: =COUNTIF(INDIRECT("'"&$D12&"'!"&U$8),"N/A") -> 0 | U12: =COUNTIF(INDIRECT("'"&$D12&"'!"&U$8),"Block") -> 0 | V12: =SUM(W12:Y12) -> 0 | W12: =COUNTIF(INDIRECT("'"&$D12&"'!"&Z$8),"Pass") -> 0 | X12: =COUNTIF(INDIRECT("'"&$D12&"'!"&Z$8),"Fail") -> 0 | Y12: =COUNTIF(INDIRECT("'"&$D12&"'!"&Z$8),"N/A") -> 0 | Z12: =COUNTIF(INDIRECT("'"&$D12&"'!"&Z$8),"Block") -> 0 | AA12: =SUM(AB12:AD12) -> 0 | AB12: =COUNTIF(INDIRECT("'"&$D12&"'!"&AE$8),"Pass") -> 0 | AC12: =COUNTIF(INDIRECT("'"&$D12&"'!"&AE$8),"Fail") -> 0 | AD12: =COUNTIF(INDIRECT("'"&$D12&"'!"&AE$8),"N/A") -> 0 | AE12: =COUNTIF(INDIRECT("'"&$D12&"'!"&AE$8),"Block") -> 0 | AF12: =SUM(AG12:AI12) -> 0 | AG12: =COUNTIF(INDIRECT("'"&$D12&"'!"&AJ$8),"Pass") -> 0 | AH12: =COUNTIF(INDIRECT("'"&$D12&"'!"&AJ$8),"Fail") -> 0 | AI12: =COUNTIF(INDIRECT("'"&$D12&"'!"&AJ$8),"N/A") -> 0 | AJ12: =COUNTIF(INDIRECT("'"&$D12&"'!"&AJ$8),"Block") -> 0 | AK12: =SUM(AL12:AN12) -> 0 | AL12: =COUNTIF(INDIRECT("'"&$D12&"'!"&AO$8),"Pass") -> 0 | AM12: =COUNTIF(INDIRECT("'"&$D12&"'!"&AO$8),"Fail") -> 0 | AN12: =COUNTIF(INDIRECT("'"&$D12&"'!"&AO$8),"N/A") -> 0 | AO12: =COUNTIF(INDIRECT("'"&$D12&"'!"&AO$8),"Block") -> 0 | AP12: =SUM(AQ12:AS12) -> 0 | AQ12: =COUNTIF(INDIRECT("'"&$D12&"'!"&AT$8),"Pass") -> 0 | AR12: =COUNTIF(INDIRECT("'"&$D12&"'!"&AT$8),"Fail") -> 0 | AS12: =COUNTIF(INDIRECT("'"&$D12&"'!"&AT$8),"N/A") -> 0 | AT12: =COUNTIF(INDIRECT("'"&$D12&"'!"&AT$8),"Block") -> 0 | AU12: =SUM(AV12:AX12) -> 0 | AV12: =COUNTIF(INDIRECT("'"&$D12&"'!"&AY$8),"Pass") -> 0 | AW12: =COUNTIF(INDIRECT("'"&$D12&"'!"&AY$8),"Fail") -> 0 | AX12: =COUNTIF(INDIRECT("'"&$D12&"'!"&AY$8),"N/A") -> 0 | AY12: =COUNTIF(INDIRECT("'"&$D12&"'!"&AY$8),"Block") -> 0 | AZ12: =SUM(BA12:BC12) -> 0 | BA12: =COUNTIF(INDIRECT("'"&$D12&"'!"&BD$8),"Pass") -> 0 | BB12: =COUNTIF(INDIRECT("'"&$D12&"'!"&BD$8),"Fail") -> 0 | BC12: =COUNTIF(INDIRECT("'"&$D12&"'!"&BD$8),"N/A") -> 0 | BD12: =COUNTIF(INDIRECT("'"&$D12&"'!"&BD$8),"Block") -> 0
B13: 4 | C13: TC_04 | D13: Hyper Fast | E13: Hyper Fast | F13: =COUNTIF(INDIRECT("'"&D13&"'!A:A"),C13&"*") -> 0 | G13: =SUM(H13:J13) -> 0 | H13: =COUNTIF(INDIRECT("'"&$D13&"'!"&K$8),"Pass") -> 0 | I13: =COUNTIF(INDIRECT("'"&$D13&"'!"&K$8),"Fail") -> 0 | J13: =COUNTIF(INDIRECT("'"&$D13&"'!"&K$8),"N/A") -> 0 | K13: =COUNTIF(INDIRECT("'"&$D13&"'!"&K$8),"Block") -> 0 | L13: =SUM(M13:O13) -> 0 | M13: =COUNTIF(INDIRECT("'"&$D13&"'!"&P$8),"Pass") -> 0 | N13: =COUNTIF(INDIRECT("'"&$D13&"'!"&P$8),"Fail") -> 0 | O13: =COUNTIF(INDIRECT("'"&$D13&"'!"&P$8),"N/A") -> 0 | P13: =COUNTIF(INDIRECT("'"&$D13&"'!"&P$8),"Block") -> 0 | Q13: =SUM(R13:T13) -> 0 | R13: =COUNTIF(INDIRECT("'"&$D13&"'!"&U$8),"Pass") -> 0 | S13: =COUNTIF(INDIRECT("'"&$D13&"'!"&U$8),"Fail") -> 0 | T13: =COUNTIF(INDIRECT("'"&$D13&"'!"&U$8),"N/A") -> 0 | U13: =COUNTIF(INDIRECT("'"&$D13&"'!"&U$8),"Block") -> 0 | V13: =SUM(W13:Y13) -> 0 | W13: =COUNTIF(INDIRECT("'"&$D13&"'!"&Z$8),"Pass") -> 0 | X13: =COUNTIF(INDIRECT("'"&$D13&"'!"&Z$8),"Fail") -> 0 | Y13: =COUNTIF(INDIRECT("'"&$D13&"'!"&Z$8),"N/A") -> 0 | Z13: =COUNTIF(INDIRECT("'"&$D13&"'!"&Z$8),"Block") -> 0 | AA13: =SUM(AB13:AD13) -> 0 | AB13: =COUNTIF(INDIRECT("'"&$D13&"'!"&AE$8),"Pass") -> 0 | AC13: =COUNTIF(INDIRECT("'"&$D13&"'!"&AE$8),"Fail") -> 0 | AD13: =COUNTIF(INDIRECT("'"&$D13&"'!"&AE$8),"N/A") -> 0 | AE13: =COUNTIF(INDIRECT("'"&$D13&"'!"&AE$8),"Block") -> 0 | AF13: =SUM(AG13:AI13) -> 0 | AG13: =COUNTIF(INDIRECT("'"&$D13&"'!"&AJ$8),"Pass") -> 0 | AH13: =COUNTIF(INDIRECT("'"&$D13&"'!"&AJ$8),"Fail") -> 0 | AI13: =COUNTIF(INDIRECT("'"&$D13&"'!"&AJ$8),"N/A") -> 0 | AJ13: =COUNTIF(INDIRECT("'"&$D13&"'!"&AJ$8),"Block") -> 0 | AK13: =SUM(AL13:AN13) -> 0 | AL13: =COUNTIF(INDIRECT("'"&$D13&"'!"&AO$8),"Pass") -> 0 | AM13: =COUNTIF(INDIRECT("'"&$D13&"'!"&AO$8),"Fail") -> 0 | AN13: =COUNTIF(INDIRECT("'"&$D13&"'!"&AO$8),"N/A") -> 0 | AO13: =COUNTIF(INDIRECT("'"&$D13&"'!"&AO$8),"Block") -> 0 | AP13: =SUM(AQ13:AS13) -> 0 | AQ13: =COUNTIF(INDIRECT("'"&$D13&"'!"&AT$8),"Pass") -> 0 | AR13: =COUNTIF(INDIRECT("'"&$D13&"'!"&AT$8),"Fail") -> 0 | AS13: =COUNTIF(INDIRECT("'"&$D13&"'!"&AT$8),"N/A") -> 0 | AT13: =COUNTIF(INDIRECT("'"&$D13&"'!"&AT$8),"Block") -> 0 | AU13: =SUM(AV13:AX13) -> 0 | AV13: =COUNTIF(INDIRECT("'"&$D13&"'!"&AY$8),"Pass") -> 0 | AW13: =COUNTIF(INDIRECT("'"&$D13&"'!"&AY$8),"Fail") -> 0 | AX13: =COUNTIF(INDIRECT("'"&$D13&"'!"&AY$8),"N/A") -> 0 | AY13: =COUNTIF(INDIRECT("'"&$D13&"'!"&AY$8),"Block") -> 0 | AZ13: =SUM(BA13:BC13) -> 0 | BA13: =COUNTIF(INDIRECT("'"&$D13&"'!"&BD$8),"Pass") -> 0 | BB13: =COUNTIF(INDIRECT("'"&$D13&"'!"&BD$8),"Fail") -> 0 | BC13: =COUNTIF(INDIRECT("'"&$D13&"'!"&BD$8),"N/A") -> 0 | BD13: =COUNTIF(INDIRECT("'"&$D13&"'!"&BD$8),"Block") -> 0
B14: 5 | C14: TC_05 | D14: Chi tiết thiết bị | E14: Chi tiết thiết bị | F14: {=COUNTIF(INDIRECT("'"&D14&"'!A:A"),C14&"*")*3} -> 0 | G14: =SUM(H14:J14) -> 0 | H14: =COUNTIF(INDIRECT("'"&$D14&"'!"&K$8),"Pass") -> 0 | I14: =COUNTIF(INDIRECT("'"&$D14&"'!"&K$8),"Fail") -> 0 | J14: =COUNTIF(INDIRECT("'"&$D14&"'!"&K$8),"N/A") -> 0 | K14: =COUNTIF(INDIRECT("'"&$D14&"'!"&K$8),"Block") -> 0 | L14: =SUM(M14:O14) -> 0 | M14: =COUNTIF(INDIRECT("'"&$D14&"'!"&P$8),"Pass") -> 0 | N14: =COUNTIF(INDIRECT("'"&$D14&"'!"&P$8),"Fail") -> 0 | O14: =COUNTIF(INDIRECT("'"&$D14&"'!"&P$8),"N/A") -> 0 | P14: =COUNTIF(INDIRECT("'"&$D14&"'!"&P$8),"Block") -> 0 | Q14: =SUM(R14:T14) -> 0 | R14: =COUNTIF(INDIRECT("'"&$D14&"'!"&U$8),"Pass") -> 0 | S14: =COUNTIF(INDIRECT("'"&$D14&"'!"&U$8),"Fail") -> 0 | T14: =COUNTIF(INDIRECT("'"&$D14&"'!"&U$8),"N/A") -> 0 | U14: =COUNTIF(INDIRECT("'"&$D14&"'!"&U$8),"Block") -> 0 | V14: =SUM(W14:Y14) -> 0 | W14: =COUNTIF(INDIRECT("'"&$D14&"'!"&Z$8),"Pass") -> 0 | X14: =COUNTIF(INDIRECT("'"&$D14&"'!"&Z$8),"Fail") -> 0 | Y14: =COUNTIF(INDIRECT("'"&$D14&"'!"&Z$8),"N/A") -> 0 | Z14: =COUNTIF(INDIRECT("'"&$D14&"'!"&Z$8),"Block") -> 0 | AA14: =SUM(AB14:AD14) -> 0 | AB14: =COUNTIF(INDIRECT("'"&$D14&"'!"&AE$8),"Pass") -> 0 | AC14: =COUNTIF(INDIRECT("'"&$D14&"'!"&AE$8),"Fail") -> 0 | AD14: =COUNTIF(INDIRECT("'"&$D14&"'!"&AE$8),"N/A") -> 0 | AE14: =COUNTIF(INDIRECT("'"&$D14&"'!"&AE$8),"Block") -> 0 | AF14: =SUM(AG14:AI14) -> 0 | AG14: =COUNTIF(INDIRECT("'"&$D14&"'!"&AJ$8),"Pass") -> 0 | AH14: =COUNTIF(INDIRECT("'"&$D14&"'!"&AJ$8),"Fail") -> 0 | AI14: =COUNTIF(INDIRECT("'"&$D14&"'!"&AJ$8),"N/A") -> 0 | AJ14: =COUNTIF(INDIRECT("'"&$D14&"'!"&AJ$8),"Block") -> 0 | AK14: =SUM(AL14:AN14) -> 0 | AL14: =COUNTIF(INDIRECT("'"&$D14&"'!"&AO$8),"Pass") -> 0 | AM14: =COUNTIF(INDIRECT("'"&$D14&"'!"&AO$8),"Fail") -> 0 | AN14: =COUNTIF(INDIRECT("'"&$D14&"'!"&AO$8),"N/A") -> 0 | AO14: =COUNTIF(INDIRECT("'"&$D14&"'!"&AO$8),"Block") -> 0 | AP14: =SUM(AQ14:AS14) -> 0 | AQ14: =COUNTIF(INDIRECT("'"&$D14&"'!"&AT$8),"Pass") -> 0 | AR14: =COUNTIF(INDIRECT("'"&$D14&"'!"&AT$8),"Fail") -> 0 | AS14: =COUNTIF(INDIRECT("'"&$D14&"'!"&AT$8),"N/A") -> 0 | AT14: =COUNTIF(INDIRECT("'"&$D14&"'!"&AT$8),"Block") -> 0 | AU14: =SUM(AV14:AX14) -> 0 | AV14: =COUNTIF(INDIRECT("'"&$D14&"'!"&AY$8),"Pass") -> 0 | AW14: =COUNTIF(INDIRECT("'"&$D14&"'!"&AY$8),"Fail") -> 0 | AX14: =COUNTIF(INDIRECT("'"&$D14&"'!"&AY$8),"N/A") -> 0 | AY14: =COUNTIF(INDIRECT("'"&$D14&"'!"&AY$8),"Block") -> 0 | AZ14: =SUM(BA14:BC14) -> 0 | BA14: =COUNTIF(INDIRECT("'"&$D14&"'!"&BD$8),"Pass") -> 0 | BB14: =COUNTIF(INDIRECT("'"&$D14&"'!"&BD$8),"Fail") -> 0 | BC14: =COUNTIF(INDIRECT("'"&$D14&"'!"&BD$8),"N/A") -> 0 | BD14: =COUNTIF(INDIRECT("'"&$D14&"'!"&BD$8),"Block") -> 0
B15: 4 | C15: TC_06 | D15: Trang tổng hợp dịch vụ | E15: Trang tổng hợp dịch vụ | F15: {=COUNTIF(INDIRECT("'"&D15&"'!A:A"),C15&"*")} -> 0 | G15: =SUM(H15:J15) -> 0 | H15: =COUNTIF(INDIRECT("'"&$D15&"'!"&K$8),"Pass") -> 0 | I15: =COUNTIF(INDIRECT("'"&$D15&"'!"&K$8),"Fail") -> 0 | J15: =COUNTIF(INDIRECT("'"&$D15&"'!"&K$8),"N/A") -> 0 | K15: =COUNTIF(INDIRECT("'"&$D15&"'!"&K$8),"Block") -> 0 | L15: =SUM(M15:O15) -> 0 | M15: =COUNTIF(INDIRECT("'"&$D15&"'!"&P$8),"Pass") -> 0 | N15: =COUNTIF(INDIRECT("'"&$D15&"'!"&P$8),"Fail") -> 0 | O15: =COUNTIF(INDIRECT("'"&$D15&"'!"&P$8),"N/A") -> 0 | P15: =COUNTIF(INDIRECT("'"&$D15&"'!"&P$8),"Block") -> 0 | Q15: =SUM(R15:T15) -> 0 | R15: =COUNTIF(INDIRECT("'"&$D15&"'!"&U$8),"Pass") -> 0 | S15: =COUNTIF(INDIRECT("'"&$D15&"'!"&U$8),"Fail") -> 0 | T15: =COUNTIF(INDIRECT("'"&$D15&"'!"&U$8),"N/A") -> 0 | U15: =COUNTIF(INDIRECT("'"&$D15&"'!"&U$8),"Block") -> 0 | V15: =SUM(W15:Y15) -> 0 | W15: =COUNTIF(INDIRECT("'"&$D15&"'!"&Z$8),"Pass") -> 0 | X15: =COUNTIF(INDIRECT("'"&$D15&"'!"&Z$8),"Fail") -> 0 | Y15: =COUNTIF(INDIRECT("'"&$D15&"'!"&Z$8),"N/A") -> 0 | Z15: =COUNTIF(INDIRECT("'"&$D15&"'!"&Z$8),"Block") -> 0 | AA15: =SUM(AB15:AD15) -> 0 | AB15: =COUNTIF(INDIRECT("'"&$D15&"'!"&AE$8),"Pass") -> 0 | AC15: =COUNTIF(INDIRECT("'"&$D15&"'!"&AE$8),"Fail") -> 0 | AD15: =COUNTIF(INDIRECT("'"&$D15&"'!"&AE$8),"N/A") -> 0 | AE15: =COUNTIF(INDIRECT("'"&$D15&"'!"&AE$8),"Block") -> 0 | AF15: =SUM(AG15:AI15) -> 0 | AG15: =COUNTIF(INDIRECT("'"&$D15&"'!"&AJ$8),"Pass") -> 0 | AH15: =COUNTIF(INDIRECT("'"&$D15&"'!"&AJ$8),"Fail") -> 0 | AI15: =COUNTIF(INDIRECT("'"&$D15&"'!"&AJ$8),"N/A") -> 0 | AJ15: =COUNTIF(INDIRECT("'"&$D15&"'!"&AJ$8),"Block") -> 0 | AK15: =SUM(AL15:AN15) -> 0 | AL15: =COUNTIF(INDIRECT("'"&$D15&"'!"&AO$8),"Pass") -> 0 | AM15: =COUNTIF(INDIRECT("'"&$D15&"'!"&AO$8),"Fail") -> 0 | AN15: =COUNTIF(INDIRECT("'"&$D15&"'!"&AO$8),"N/A") -> 0 | AO15: =COUNTIF(INDIRECT("'"&$D15&"'!"&AO$8),"Block") -> 0 | AP15: =SUM(AQ15:AS15) -> 0 | AQ15: =COUNTIF(INDIRECT("'"&$D15&"'!"&AT$8),"Pass") -> 0 | AR15: =COUNTIF(INDIRECT("'"&$D15&"'!"&AT$8),"Fail") -> 0 | AS15: =COUNTIF(INDIRECT("'"&$D15&"'!"&AT$8),"N/A") -> 0 | AT15: =COUNTIF(INDIRECT("'"&$D15&"'!"&AT$8),"Block") -> 0 | AU15: =SUM(AV15:AX15) -> 0 | AV15: =COUNTIF(INDIRECT("'"&$D15&"'!"&AY$8),"Pass") -> 0 | AW15: =COUNTIF(INDIRECT("'"&$D15&"'!"&AY$8),"Fail") -> 0 | AX15: =COUNTIF(INDIRECT("'"&$D15&"'!"&AY$8),"N/A") -> 0 | AY15: =COUNTIF(INDIRECT("'"&$D15&"'!"&AY$8),"Block") -> 0 | AZ15: =SUM(BA15:BC15) -> 0 | BA15: =COUNTIF(INDIRECT("'"&$D15&"'!"&BD$8),"Pass") -> 0 | BB15: =COUNTIF(INDIRECT("'"&$D15&"'!"&BD$8),"Fail") -> 0 | BC15: =COUNTIF(INDIRECT("'"&$D15&"'!"&BD$8),"N/A") -> 0 | BD15: =COUNTIF(INDIRECT("'"&$D15&"'!"&BD$8),"Block") -> 0
B16: Total | F16: =SUM(F10:F15) -> 300 | G16: =SUM(G10:G15) -> 0 | H16: =SUM(H10:H14) -> 0 | I16: =SUM(I10:I15) -> 0 | J16: =SUM(J10:J15) -> 0 | K16: =SUM(K10:K15) -> 0 | L16: =SUM(L10) -> 0 | M16: =SUM(M10) -> 0 | N16: =SUM(N10) -> 0 | O16: =SUM(O10) -> 0 | P16: =SUM(P10) -> 0 | Q16: =SUM(Q10) -> 0 | R16: =SUM(R10) -> 0 | S16: =SUM(S10) -> 0 | ... BD16: =SUM(BD10) -> 0
B17: Rate (%) | G17: =IFERROR(G16/$F$16,0) -> 0 | H17: =IFERROR(H16/G$16,0) -> 0 | I17: =IFERROR(I16/G$16,0) -> 0 | J17: =IFERROR(J16/G$16,0) -> 0 | K17: =IFERROR(K16/$F$16,0) -> 0 | L17: =IFERROR(L16/$F$16,0) -> 0 | M17: =IFERROR(M16/L$16,0) -> 0 | N17: =IFERROR(N16/L$16,0) -> 0 | O17: =IFERROR(O16/L$16,0) -> 0 | P17: =IFERROR(P16/$F$16,0) -> 0 | Q17: =IFERROR(Q16/$F$16,0) -> 0 | R17: =IFERROR(R16/Q$16,0) -> 0 | S17: =IFERROR(S16/Q$16,0) -> 0 | T17: =IFERROR(T16/Q$16,0) -> 0 | U17: =IFERROR(U16/$F$16,0) -> 0 | V17: =IFERROR(V16/$F$16,0) -> 0 | W17: =IFERROR(W16/V$16,0) -> 0 | X17: =IFERROR(X16/V$16,0) -> 0 | Y17: =IFERROR(Y16/V$16,0) -> 0 | Z17: =IFERROR(Z16/$F$16,0) -> 0 | AA17: =IFERROR(AA16/$F$16,0) -> 0 | AB17: =IFERROR(AB16/AA$16,0) -> 0 | AC17: =IFERROR(AC16/AA$16,0) -> 0 | AD17: =IFERROR(AD16/AA$16,0) -> 0 | AE17: =IFERROR(AE16/$F$16,0) -> 0 | AF17: =IFERROR(AF16/$F$16,0) -> 0 | AG17: =IFERROR(AG16/AF$16,0) -> 0 | AH17: =IFERROR(AH16/AF$16,0) -> 0 | AI17: =IFERROR(AI16/AF$16,0) -> 0 | AJ17: =IFERROR(AJ16/$F$16,0) -> 0 | AK17: =IFERROR(AK16/$F$16,0) -> 0 | AL17: =IFERROR(AL16/AK$16,0) -> 0 | AM17: =IFERROR(AM16/AK$16,0) -> 0 | AN17: =IFERROR(AN16/AK$16,0) -> 0 | AO17: =IFERROR(AO16/$F$16,0) -> 0 | AP17: =IFERROR(AP16/$F$16,0) -> 0 | AQ17: =IFERROR(AQ16/AP$16,0) -> 0 | AR17: =IFERROR(AR16/AP$16,0) -> 0 | AS17: =IFERROR(AS16/AP$16,0) -> 0 | AT17: =IFERROR(AT16/$F$16,0) -> 0 | AU17: =IFERROR(AU16/$F$16,0) -> 0 | AV17: =IFERROR(AV16/AU$16,0) -> 0 | AW17: =IFERROR(AW16/AU$16,0) -> 0 | AX17: =IFERROR(AX16/AU$16,0) -> 0 | AY17: =IFERROR(AY16/$F$16,0) -> 0 | AZ17: =IFERROR(AZ16/$F$16,0) -> 0 | BA17: =IFERROR(BA16/AZ$16,0) -> 0 | BB17: =IFERROR(BB16/AZ$16,0) -> 0 | BC17: =IFERROR(BC16/AZ$16,0) -> 0 | BD17: =IFERROR(BD16/$F$16,0) -> 0

Sheet Đặc tính
B3: Mã chức năng (Function ID) | D3: TC_03
B4: Tên chức năng (Function Name) | D4: Đặc tính
A7: QC/AI | B7: Testcase ID | C7: Mức Độ Ưu Tiên (Priority) | D7: Nội Dung Test (Test Title) | E7: Điều Kiện/ Dữ Liệu Test (Pre-condition/ Test Data) | F7: Các Bước Thực Hiện (Test Steps) | G7: Kết Quả Mong Đợi (Expected Results) | H7: =#REF! -> #REF!
H8: Kết Quả Thực Hiện (Actual Result) | I8: Người Thực Hiện (Executed By) | J8: ID Bugs | K8: Ghi Chú (Remark)
B9: Xem danh sách nhóm đặc tính
B10: =IF(D10="","",$D$3&"."&COUNTA($D$9:D10)&"") -> TC_03.1 | C10: Medium | D10: Check nhóm quyền thao tác xem danh sách nhóm đặc tính | F10: 1. Check quyền thao tác xem danh sách nhóm đặc tính | G10: Người quản trị mở chức năng Đặc tính
B11: =IF(D11="","",$D$3&"."&COUNTA($D$9:D11)&"") -> TC_03.2 | C11: Medium | D11: Check menu vào màn hình Danh sách đặc tính | F11: 1. Login thành công vào hệ thống 2. Check Menu vào màn hình Danh sách đặc tính | G11: Menu vào màn hình Danh sách đặt tính: - Left Menu ProductHub > Đặc tính
B12: =IF(D12="","",$D$3&"."&COUNTA($D$9:D12)&"") -> TC_03.3 | C12: Medium | D12: Check GUI Danh sách nhóm đặc tính | F12: 1. Login thành công vào hệ thống 2. Click Menu ProductHub > Đặc tính 3. Check GUI Danh sách nhóm đặc tính | G12: GUI danh sách đặc tính gồm: - Tiêu đề chính “ProductHub” - Tab “Nhóm đặc tính” - Tab “Đặc tính” - Textbox: Ô tìm kiếm theo tên - Nút “Tìm kiếm” - Nút “+ Tạo mới nhóm đặc tính” - Bảng danh sách nhóm đặc tính sản phẩm - Thanh phân trang Pagination
B13: =IF(D13="","",$D$3&"."&COUNTA($D$9:D13)&"") -> TC_03.4 | C13: Medium | D13: Check Tìm kiếm theo Nhóm đặc tính | F13: 1. Login thành công vào hệ thống 2. Click Menu ProductHub > Đặc tính 3. Fill Tên nhóm đặc tính 4. Click btn Tìm kiếm hoặc nhấn Enter | G13: Trên Bảng danh sách nhóm đặc tính sản phẩm hiển thị dữ liệu thỏa điều kiện đang Filter
B14: =IF(D14="","",$D$3&"."&COUNTA($D$9:D14)&"") -> TC_03.5 | C14: Medium | D14: Check Tìm kiếm theo Tên đặc tính | F14: 1. Login thành công vào hệ thống 2. Click Menu ProductHub > Đặc tính 3. Fill Tên đặc tính 4. Click btn Tìm kiếm hoặc nhấn Enter | G14: Trên Bảng danh sách nhóm đặc tính sản phẩm hiển thị dữ liệu thỏa điều kiện đang Filter
B15: =IF(D15="","",$D$3&"."&COUNTA($D$9:D15)&"") -> TC_03.6 | C15: Medium | D15: Check tìm kiếm theo Nhóm/ Tên đặc tính trước or sau có khoảng trắng | F15: 1. Login thành công vào hệ thống 2. Click Menu ProductHub > Đặc tính 3. Check tìm kiếm theo Nhóm/ Tên đặc tính trước or sau có khoảng trắng 4. Click btn Tìm kiếm | G15: Tự động clear khoảng trắng trước or sau dữ liệu tìm kiếm - Hiển thị dữ liệu thỏa điều kiện đang filter
B16: =IF(D16="","",$D$3&"."&COUNTA($D$9:D16)&"") -> TC_03.7 | C16: Medium | D16: Check tìm kiếm theo Nhóm/ Tên đặc tính có ký tự hoa thường | F16: 1. Login thành công vào hệ thống 2. Click Menu ProductHub > Đặc tính 3. Check tìm kiếm theo Nhóm/ Tên đặc tính trước or sau có khoảng trắng 4. Click btn Tìm kiếm | G16: Cho phép người dùng nhập từ khóa để tìm nhóm đặc tính hoặc đặc tính theo tên. Tìm kiếm không phân biệt hoa/thường. - Hiển thị dữ liệu thỏa điều kiện đang Filter
B17: =IF(D17="","",$D$3&"."&COUNTA($D$9:D17)&"") -> TC_03.8 | C17: Medium | D17: Check Load dữ liệu ở Bảng danh sách nhóm đặc tính sản phẩm | F17: 1. Login thành công vào hệ thống 2. Click Menu ProductHub > Đặc tính 3. Check Load dữ liệu ở Bảng danh sách nhóm đặc tính sản phẩm | G17: Bảng danh sách nhóm đặc tính sản phẩm gồm: - Tên nhóm đặc tính - Tên đặc tính - Thời gian cập nhật - Người cập nhật - Thời gian tạo - Người tạo - Thao tác (Icon group (👁, ✏️)
B18: =IF(D18="","",$D$3&"."&COUNTA($D$9:D18)&"") -> TC_03.9 | C18: Medium | D18: Check hiển thị tên nhóm đặc tính | F18: 1. Login thành công vào hệ thống 2. Click Menu ProductHub > Đặc tính 3. Load dữ liệu ở Bảng danh sách nhóm đặc tính sản phẩm 4. Check hiển thị tên nhóm đặc tính | G18: Hiển thị đúng Tên nhóm đặc tính ví dụ: Internet, FPT Play, Camera… Click vào từng dòng tên nhóm đặc tính, hệ thống mở popup chi tiết nhóm đặc tính đấy.
B19: =IF(D19="","",$D$3&"."&COUNTA($D$9:D19)&"") -> TC_03.10 | C19: Medium | D19: Check hiển thị Tên đặc tính | F19: 1. Login thành công vào hệ thống 2. Click Menu ProductHub > Đặc tính 3. Load dữ liệu ở Bảng danh sách nhóm đặc tính sản phẩm 4. Check hiển thị Tên đặc tính | G19: Hiển thị danh sách các đặc tính thuộc nhóm dưới dạng thẻ (tag). Mặc định hiển thị 2 thẻ đầu tiên, phần còn lại hiển thị “+X more”.
B20: =IF(D20="","",$D$3&"."&COUNTA($D$9:D20)&"") -> TC_03.11 | C20: Medium | D20: Check hiển thị Thời gian cập nhật | F20: 1. Login thành công vào hệ thống 2. Click Menu ProductHub > Đặc tính 3. Load dữ liệu ở Bảng danh sách nhóm đặc tính sản phẩm 4. Check hiển thị Thời gian cập nhật | G20: Hiển thị thời gian cập nhật gần nhất, định dạng dd/MM/yyyy HH:mm, sử dụng hệ giờ 24h.
B21: =IF(D21="","",$D$3&"."&COUNTA($D$9:D21)&"") -> TC_03.12 | C21: Medium | D21: Check hiển thị Người cập nhật | F21: 1. Login thành công vào hệ thống 2. Click Menu ProductHub > Đặc tính 3. Load dữ liệu ở Bảng danh sách nhóm đặc tính sản phẩm 4. Check hiển thị Người cập nhật | G21: Hiển thị username hoặc mã người dùng thực hiện cập nhật gần nhất. Khi tạo mới, thời gian cập nhật = thời gian tạo. Danh sách được sắp xếp theo thời gian cập nhật (last update), trong đó các nhóm đặc tính được cập nhật gần nhất sẽ hiển thị ở đầu danh sách.
... B27: =IF(D27="","",$D$3&"."&COUNTA($D$9:D27)&"") -> TC_03.18 | C27: Medium | D27: Check click btn Tạo mới nhóm đặc tính | F27: 1. Login thành công vào hệ thống 2. Click Menu ProductHub > Đặc tính 3. Load dữ liệu ở Bảng danh sách nhóm đặc tính sản phẩm 4. Check click btn Tạo mới nhóm đặc tính | G27: Hiển thị ở góc phải phía trên bảng.Hiển thị Popup Nhóm đặc tính
B28: Tạo mới nhóm đặc tính
B29: =IF(D29="","",$D$3&"."&COUNTA($D$9:D29)&"") -> TC_03.19 | C29: Medium | D29: Check Popup Tạo mới nhóm đặc tính | F29: 1. Login thành công vào hệ thống 2. Click Menu ProductHub > Đặc tính 3. Click btn Tạo mới nhóm đặc tính 5. Check Popup Tạo mới nhóm đặc tính | G29: Hiển thị ở góc phải phía trên bảng.Hiển thị Popup Nhóm đặc tính: - Title popup: Tạo mới nhóm đặc tính - Textbox: Tên nhóm đặc tính (*) - Placeholder: Nhập tên nhóm đặc tính - Droplist: Chọn đặc tính - btn Hủy - btn Tạo - icon x (đóng popup)
B30: =IF(D30="","",$D$3&"."&COUNTA($D$9:D30)&"") -> TC_03.20 | C30: Medium | D30: Check Tạo mới khi không Nhập tên nhóm đặc tính | F30: 1. Popup Tạo mới nhóm đặc tính 2. Check Tạo mới khi không Nhập tên nhóm đặc tính 3. Click btn Tạo | G30: “Vui lòng nhập tên nhóm đặc tính!”.
B31: =IF(D31="","",$D$3&"."&COUNTA($D$9:D31)&"") -> TC_03.21 | C31: Medium | D31: Check Tạo mới khi Nhập tên nhóm đặc tính là khoảng trắng | F31: 1. Popup Tạo mới nhóm đặc tính 2. Check Tạo mới khi Nhập tên nhóm đặc tính là khoảng trắng 3. Click btn Tạo | G31: “Vui lòng nhập tên nhóm đặc tính!”.
B32: =IF(D32="","",$D$3&"."&COUNTA($D$9:D32)&"") -> TC_03.22 | C32: Medium | D32: Check Tạo mới nhưng Nhập tên nhóm đặc tính quá dài | F32: 1. Popup Tạo mới nhóm đặc tính 2. Check Tạo mới nhưng Nhập tên nhóm đặc tính quá dài 3. Click btn Tạo | G32: Hiển thị cảnh báo: "Tên nhóm đặc tính tối đa 255 ký tự"
B33: =IF(D33="","",$D$3&"."&COUNTA($D$9:D33)&"") -> TC_03.23 | C33: Medium | D33: Check load data Droplist Đặc tính | F33: 1. Popup Tạo mới nhóm đặc tính 2. Check load data Droplist Đặc tính | G33: Hệ thống hiển thị dữ liệu đặc tính gồm: - Danh sách đặc tính trong dropdown được lấy từ các đặc tính đã được cấu hình. - Cho phép người dùng chọn đặc tính có sẵn trong hệ thống để gán vào nhóm. - Hỗ trợ tìm kiếm theo từ khóa và hiển thị dưới dạng tag
B34: =IF(D34="","",$D$3&"."&COUNTA($D$9:D34)&"") -> TC_03.24 | C34: Medium | D34: Check Chọn nhiều đặc tính trong dropdown | F34: 1. Popup Tạo mới nhóm đặc tính 2. Check Chọn nhiều đặc tính trong dropdown | G34: Các đặc tính hiển thị dưới dạng tag
B35: =IF(D35="","",$D$3&"."&COUNTA($D$9:D35)&"") -> TC_03.25 | C35: Medium | D35: Check Xoá một đặc tính đã chọn (dạng tag) | F35: 1. Popup Tạo mới nhóm đặc tính 2. Check Xoá một đặc tính đã chọn (dạng tag) | G35: Tag đặc tính bị xoá khỏi danh sách chọn
B36: =IF(D36="","",$D$3&"."&COUNTA($D$9:D36)&"") -> TC_03.26 | C36: Medium | D36: Check Tạo mới nhóm đặc tính nhưng không chọn đặc tính | F36: 1. Popup Tạo mới nhóm đặc tính 2. Check Tạo mới nhóm đặc tính nhưng không chọn đặc tính 3. Click btn Tạo | G36: Cho phép tạo Nhóm đặc tính thành công
B37: =IF(D37="","",$D$3&"."&COUNTA($D$9:D37)&"") -> TC_03.27 | C37: Medium | D37: Check Tạo Nhóm đặc tính trùng trong hệ thống | F37: 1. Popup Tạo mới nhóm đặc tính 2. Check Tạo Nhóm đặc tính trùng trong hệ thống 3. Click btn Tạo | G37: “Tên nhóm đặc tính đã tồn tại. Vui lòng nhập tên khác!”
B38: =IF(D38="","",$D$3&"."&COUNTA($D$9:D38)&"") -> TC_03.28 | C38: Medium | D38: Check Tạo nhóm đặc tính mà có nhiều đặc tính trùng nhau | F38: 1. Popup Tạo mới nhóm đặc tính 2. Check Tạo nhóm đặc tính mà có nhiều đặc tính trùng nhau 3. Click btn Tạo | G38: - Trong 1 nhóm đặc tính không có 2 cấu hình đặc tính trùng nhau. - Không cho phép tạo 2 đặc tính trùng nhau trong hệ thống
B39: =IF(D39="","",$D$3&"."&COUNTA($D$9:D39)&"") -> TC_03.29 | C39: Medium | D39: Check Click btn Hủy | F39: 1. Popup Tạo mới nhóm đặc tính 2. Check Click btn Hủy | G39: Đóng popup “Tạo mới nhóm đặc tính”, quay về màn danh sách nhóm đặc tính.
B40: =IF(D40="","",$D$3&"."&COUNTA($D$9:D40)&"") -> TC_03.30 | C40: Medium | D40: Check Tạo mới nhóm đặc tính | F40: 1. Popup Tạo mới nhóm đặc tính 2. Check Tạo mới nhóm đặc tính 3. Click btn Tạo | G40: Thành công: “Tạo nhóm đặc tính thành công.” - Popup đóng lại - Nhóm mới xuất hiện ở danh sách màn hình chính
... B42: =IF(D42="","",$D$3&"."&COUNTA($D$9:D42)&"") -> TC_03.32 | C42: Medium | D42: Check thông báo khi Lỗi lưu dữ liệu hệ thống | F42: 1. Nhập thông tin hợp lệ 2. Nhấn “Tạo | G42: Hiển thị lỗi: "Không thể tạo nhóm đặc tính. Vui lòng thử lại sau." Không tạo dữ liệu
B43: Chi tiết nhóm đặc tính
B44: =IF(D44="","",$D$3&"."&COUNTA($D$9:D44)&"") -> TC_03.33 | C44: Medium | D44: Check hiển thị Popup Chi tiết nhóm đặc tính | F44: 1. Vào ProductHub → tab "Đặc tính" 2. Click tên nhóm đặc tính / icon 👁 | G44: Hiển thị popup “Chi tiết nhóm đặc tính” với các trường: - Tên nhóm, - Danh sách đặc tính (tag), - nút Đóng - icon X
B45: =IF(D45="","",$D$3&"."&COUNTA($D$9:D45)&"") -> TC_03.34 | C45: Medium | D45: Check load đúng tên nhóm đặc tính | F45: 1. Popup Chi tiết nhóm đặc tính 2. Check load đúng tên nhóm đặc tính | G45: Trường Tên nhóm hiển thị đúng giá trị theo DB
B46: =IF(D46="","",$D$3&"."&COUNTA($D$9:D46)&"") -> TC_03.35 | C46: Medium | D46: Check Load danh sách đặc tính thuộc nhóm | F46: 1. Popup Chi tiết nhóm đặc tính 2. Check Load danh sách đặc tính thuộc nhóm | G46: Danh sách tag đặc tính hiển thị đúng với DB (đúng số lượng & tên)
B47: =IF(D47="","",$D$3&"."&COUNTA($D$9:D47)&"") -> TC_03.36 | C47: Medium | D47: Check Nhóm không có đặc tính được gán | F47: 1. Popup Chi tiết nhóm đặc tính 2. Nhóm không có đặc tính được gán | G47: Khu vực danh sách tag hiển thị rỗng hoặc thông báo: “Chưa có đặc tính gán vào nhóm”
B48: =IF(D48="","",$D$3&"."&COUNTA($D$9:D48)&"") -> TC_03.37 | C48: Medium | D48: Check Đóng popup từ button “Đóng” | F48: 1. Popup Chi tiết nhóm đặc tính 2. Đóng popup từ button “Đóng” | G48: Popup biến mất, trở về màn hình danh sách
B49: =IF(D49="","",$D$3&"."&COUNTA($D$9:D49)&"") -> TC_03.38 | C49: Medium | D49: Check Đóng popup bằng click ra ngoài overlay | F49: 1. Popup Chi tiết nhóm đặc tính 2. Check Đóng popup bằng click ra ngoài overlay | G49: Popup đóng, quay lại màn hình danh sách
B50: =IF(D50="","",$D$3&"."&COUNTA($D$9:D50)&"") -> TC_03.39 | C50: Medium | D50: Kiểm tra hiển thị ký tự đặc biệt trong tên nhóm | F50: 1. Popup Chi tiết nhóm đặc tính 2. Kiểm tra hiển thị ký tự đặc biệt trong tên nhóm | G50: Hiển thị đúng định dạng, không bị cắt ký tự
...

Sheet QL nội dung gói bán
B3: Mã chức năng (Function ID) | D3: TC_05
B4: Tên chức năng (Function Name) | D4: Chi tiết thiết bị
A7: QC/AI | B7: Testcase ID | C7: Mức Độ Ưu Tiên (Priority) | D7: Nội Dung Test (Test Title) | E7: Điều Kiện/ Dữ Liệu Test (Pre-condition/ Test Data) | F7: Các Bước Thực Hiện (Test Steps) | G7: Kết Quả Mong Đợi (Expected Results) | H7: =#REF! -> #REF!
H8: Kết Quả Thực Hiện (Actual Result) | I8: Người Thực Hiện (Executed By) | J8: ID Bugs | K8: Ghi Chú (Remark)
B9: DANH SÁCH NỘI DUNG GÓI BÁN
B10: =IF(F10="","",$D$3&"."&COUNTA($F$9:F10)&"") -> TC_05.1 | C10: High | D10: Kiểm tra truy cập màn hình Danh sách khi người dùng không có quyền | E10: 1. Người dùng đã đăng nhập hệ thống. 2. Tài khoản KHÔNG có quyền 'Xem danh sách nội dung Gói bán'. | F10: 1. Truy cập menu Nội dung hiển thị. 2. Chọn Gói bán. | G10: Hệ thống hiển thị thông báo lỗi: 'Bạn không có quyền truy cập chức năng này'. Danh sách không được hiển thị.
B11: =IF(F11="","",$D$3&"."&COUNTA($F$9:F11)&"") -> TC_05.2 | C11: High | D11: Kiểm tra truy cập màn hình Danh sách khi người dùng có quyền hợp lệ | E11: 1. Người dùng đã đăng nhập hệ thống. 2. Tài khoản có quyền 'Xem danh sách nội dung Gói bán'. | F11: 1. Truy cập menu Nội dung hiển thị. 2. Chọn Gói bán. | G11: Hệ thống điều hướng thành công đến màn hình Danh sách nội dung Gói bán. Tiêu đề 'Danh sách nội dung gói bán' được hiển thị.
B12: =IF(F12="","",$D$3&"."&COUNTA($F$9:F12)&"") -> TC_05.3 | C12: Medium | D12: Kiểm tra truy cập màn hình Danh sách khi chưa đăng nhập | E12: Người dùng CHƯA đăng nhập hệ thống. | F12: 1. Truy cập trực tiếp URL màn hình Danh sách nội dung Gói bán. | G12: Hệ thống chuyển hướng về trang đăng nhập. Danh sách nội dung không được hiển thị.
B13: =IF(F13="","",$D$3&"."&COUNTA($F$9:F13)&"") -> TC_05.4 | C13: High | D13: Kiểm tra hiển thị danh sách khi có dữ liệu trong hệ thống | E13: 1. Đã đăng nhập, có quyền xem. 2. Hệ thống có dữ liệu nội dung gói bán được tạo. | F13: 1. Truy cập menu Nội dung hiển thị. 2. Chọn Gói bán. 3. Quan sát danh sách hiển thị. | G13: Danh sách gói bán hiển thị đủ các cột: STT, Gói bán, Kênh bán, Thời gian cập nhật, Người cập nhật, Thời gian tạo, Người tạo, Icon '...'. Mặc định hiển thị 20 bản ghi đầu tiên.
B14: =IF(F14="","",$D$3&"."&COUNTA($F$9:F14)&"") -> TC_05.5 | C14: High | D14: Kiểm tra hiển thị danh sách khi không có dữ liệu trong hệ thống | E14: 1. Đã đăng nhập, có quyền xem. 2. Hệ thống KHÔNG có dữ liệu gói bán. | F14: 1. Truy cập menu Nội dung hiển thị. 2. Chọn Gói bán. 3. Quan sát khu vực hiển thị danh sách. | G14: Danh sách rỗng. Hệ thống hiển thị thông báo: 'Không có dữ liệu'.
B15: =IF(F15="","",$D$3&"."&COUNTA($F$9:F15)&"") -> TC_05.6 | C15: High | D15: Kiểm tra sắp xếp danh sách theo thời gian cập nhật gần nhất (giảm dần) | E15: 1. Đã đăng nhập, có quyền xem. 2. Hệ thống có nhiều bản ghi với thời gian cập nhật khác nhau. | F15: 1. Truy cập menu Nội dung hiển thị. 2. Chọn Gói bán. 3. Quan sát thứ tự các bản ghi theo cột 'Thời gian cập nhật'. | G15: Bản ghi có 'Thời gian cập nhật' mới nhất được hiển thị đầu tiên (sắp xếp giảm dần theo thời gian cập nhật).
A16: AI | B16: =IF(F16="","",$D$3&"."&COUNTA($F$9:F16)&"") -> TC_05.7 | C16: Medium | D16: Kiểm tra phân trang - hiển thị 20 bản ghi mặc định mỗi trang | E16: 1. Đã đăng nhập, có quyền xem. 2. Hệ thống có hơn 21 bản ghi gói bán. | F16: 1. Truy cập menu Nội dung hiển thị. 2. Chọn Gói bán. 3. Đếm số bản ghi hiển thị trên trang đầu tiên. | G16: Trang đầu tiên hiển thị đúng 20 bản ghi. Thanh điều hướng trang được hiển thị.
A17: AI | B17: =IF(F17="","",$D$3&"."&COUNTA($F$9:F17)&"") -> TC_05.8 | C17: Medium | D17: Kiểm tra phân trang - chuyển sang trang tiếp theo | E17: 1. Đã đăng nhập, có quyền xem. 2. Hệ thống có hơn 11 bản ghi gói bán. | F17: 1. Truy cập menu Nội dung hiển thị. 2. Chọn Gói bán. 3. Nhấn nút điều hướng sang trang 2. 4. Quan sát danh sách trang 2. | G17: Trang 2 hiển thị đúng các bản ghi tiếp theo. STT tiếp tục từ bản ghi thứ 21.
B18: =IF(F18="","",$D$3&"."&COUNTA($F$9:F18)&"") -> TC_05.9 | C18: Low | D18: Kiểm tra định dạng cột 'Thời gian cập nhật' đúng dd/mm/yyyy HH:mm | E18: 1. Đã đăng nhập, có quyền xem. 2. Hệ thống có dữ liệu nội dung gói bán được tạo. | F18: 1. Truy cập menu Nội dung hiển thị. 2. Chọn Gói bán. 3. Quan sát giá trị hiển thị trong cột 'Thời gian cập nhật' của bất kỳ bản ghi nào. | G18: Cột 'Thời gian cập nhật' hiển thị đúng định dạng dd/mm/yyyy HH:mm (24h). Ví dụ: 28/03/2026 14:30.
B19: =IF(F19="","",$D$3&"."&COUNTA($F$9:F19)&"") -> TC_05.10 | C19: Low | D19: Kiểm tra định dạng cột 'Thời gian tạo' đúng dd/mm/yyyy HH:mm | E19: 1. Đã đăng nhập, có quyền xem. 2. Hệ thống có dữ liệu nội dung gói bán được tạo. | F19: 1. Truy cập menu Nội dung hiển thị. 2. Chọn Gói bán. 3. Quan sát giá trị hiển thị trong cột 'Thời gian tạo' của bất kỳ bản ghi nào. | G19: Cột 'Thời gian tạo' hiển thị đúng định dạng dd/mm/yyyy HH:mm (24h). Ví dụ: 01/01/2026 09:00.
B20: =IF(F20="","",$D$3&"."&COUNTA($F$9:F20)&"") -> TC_05.11 | C20: High | D20: Kiểm tra tìm kiếm theo tên gói bán - từ khóa khớp chính xác | E20: 1. Đã đăng nhập, có quyền xem. 2. Hệ thống có ít nhất 1 gói bán tên 'Gói Internet 100Mbps'. | F20: 1. Truy cập menu Nội dung hiển thị. 2. Chọn Gói bán. 3. Nhập từ khóa 'Gói Internet 100Mbps' vào ô tìm kiếm. 4. Nhấn nút 'Tìm kiếm'. 5. Quan sát kết quả trả về trong danh sách. | G20: Danh sách chỉ hiển thị bản ghi 'Gói Internet 100Mbps'. Các bản ghi không khớp bị ẩn.
B21: =IF(F21="","",$D$3&"."&COUNTA($F$9:F21)&"") -> TC_05.12 | C21: High | D21: Kiểm tra tìm kiếm không phân biệt hoa/thường | E21: 1. Đã đăng nhập, có quyền xem. 2. Hệ thống có gói bán tên 'Gói Internet 100Mbps'. | F21: 1. Truy cập menu Nội dung hiển thị. 2. Chọn Gói bán. 3. Nhập từ khóa 'gói internet 100mbps' (chữ thường) vào ô tìm kiếm. 4. Nhấn nút 'Tìm kiếm'. 5. Quan sát kết quả trả về trong danh sách. | G21: Danh sách hiển thị bản ghi 'Gói Internet 100Mbps'. Hệ thống không phân biệt hoa/thường.
B22: =IF(F22="","",$D$3&"."&COUNTA($F$9:F22)&"") -> TC_05.13 | C22: High | D22: Kiểm tra tìm kiếm bằng phím Enter | E22: 1. Đã đăng nhập, có quyền xem. 2. Hệ thống có gói bán chứa từ 'Internet'. | F22: 1. Truy cập menu Nội dung hiển thị. 2. Chọn Gói bán. 3. Nhập từ khóa 'Internet' vào ô tìm kiếm. 4. Nhấn phím Enter. 5. Quan sát kết quả trả về trong danh sách. | G22: Danh sách hiển thị các bản ghi có tên chứa 'Internet'. Kết quả tương đương với nhấn nút 'Tìm kiếm'.
B23: =IF(F23="","",$D$3&"."&COUNTA($F$9:F23)&"") -> TC_05.14 | C23: Medium | D23: Kiểm tra tìm kiếm với từ khóa một phần (partial match) | E23: 1. Đã đăng nhập, có quyền xem. 2. Hệ thống có 'Gói Internet 100Mbps' và 'Gói Internet 200Mbps'. | F23: 1. Truy cập menu Nội dung hiển thị. 2. Chọn Gói bán. 3. Nhập từ khóa 'Internet' vào ô tìm kiếm. 4. Nhấn nút 'Tìm kiếm'. 5. Quan sát kết quả trả về trong danh sách. | G23: Danh sách hiển thị cả 'Gói Internet 100Mbps' và 'Gói Internet 200Mbps'. Hệ thống hỗ trợ tìm kiếm substring.
B24: =IF(F24="","",$D$3&"."&COUNTA($F$9:F24)&"") -> TC_05.15 | C24: High | D24: Kiểm tra tìm kiếm không có kết quả | E24: 1. Đã đăng nhập, có quyền xem. 2. Hệ thống có dữ liệu nội dung gói bán được tạo. | F24: 1. Truy cập menu Nội dung hiển thị. 2. Chọn Gói bán. 3. Nhập từ khóa 'XYZXYZXYZ_khong_ton_tai' vào ô tìm kiếm. 4. Nhấn nút 'Tìm kiếm'. 5. Quan sát khu vực hiển thị danh sách. | G24: Danh sách rỗng. Hệ thống hiển thị thông báo: 'Không tìm thấy kết quả phù hợp'.
A25: AI | B25: =IF(F25="","",$D$3&"."&COUNTA($F$9:F25)&"") -> TC_05.16 | C25: Medium | D25: Kiểm tra tìm kiếm với ô tìm kiếm để trống | E25: 1. Đã đăng nhập, có quyền xem. 2. Hệ thống có dữ liệu nội dung gói bán được tạo. | F25: 1. Truy cập menu Nội dung hiển thị. 2. Chọn Gói bán. 3. Để trống ô tìm kiếm. 4. Nhấn nút 'Tìm kiếm'. 5. Quan sát danh sách hiển thị. | G25: Hệ thống hiển thị toàn bộ danh sách gói bán (20 bản ghi mặc định/trang).
B26: =IF(F26="","",$D$3&"."&COUNTA($F$9:F26)&"") -> TC_05.17 | C26: Low | D26: Kiểm tra placeholder ô tìm kiếm | E26: Đã đăng nhập, có quyền xem. | F26: 1. Truy cập menu Nội dung hiển thị. 2. Chọn Gói bán. 3. Quan sát ô tìm kiếm khi chưa nhập dữ liệu. | G26: Ô tìm kiếm hiển thị placeholder text: 'Tìm kiếm gói bán'.
B27: =IF(F27="","",$D$3&"."&COUNTA($F$9:F27)&"") -> TC_05.18 | C27: Medium | D27: Kiểm tra tìm kiếm với ký tự đặc biệt (XSS) | E27: 1. Đã đăng nhập, có quyền xem. 2. Hệ thống có dữ liệu nội dung gói bán được tạo. | F27: 1. Truy cập menu Nội dung hiển thị. 2. Chọn Gói bán. 3. Nhập ký tự '<script>alert(1)</script>' vào ô tìm kiếm. 4. Nhấn nút 'Tìm kiếm'. 5. Quan sát phản hồi của hệ thống. | G27: Hệ thống xử lý an toàn, không thực thi script. Hiển thị kết quả rỗng hoặc không tìm thấy. Không có lỗi XSS.
B28: =IF(F28="","",$D$3&"."&COUNTA($F$9:F28)&"") -> TC_05.19 | C28: High | D28: Kiểm tra nhấn 'Chỉnh sửa' | E28: 1. Đã đăng nhập, có quyền xem và quyền chỉnh sửa. 2. Danh sách có ít nhất 1 bản ghi. | F28: 1. Truy cập menu Nội dung hiển thị. 2. Chọn Gói bán. 3. Nhấn 'Chỉnh sửa'. | G28: Hệ thống điều hướng đến màn hình Chỉnh sửa nội dung gói bán với dữ liệu của bản ghi đó được load sẵn.
B29: =IF(F29="","",$D$3&"."&COUNTA($F$9:F29)&"") -> TC_05.20 | C29: High | D29: Kiểm tra nhấn nút '+ Tạo mới' điều hướng đến màn hình Tạo mới | E29: 1. Đã đăng nhập, có quyền xem và quyền tạo mới. | F29: 1. Truy cập menu Nội dung hiển thị. 2. Chọn Gói bán. 3. Nhấn nút '+ Tạo mới'. | G29: Hệ thống điều hướng đến màn hình Tạo mới nội dung Gói bán. Tất cả các trường ở trạng thái trống hoặc giá trị mặc định.
B30: =IF(F30="","",$D$3&"."&COUNTA($F$9:F30)&"") -> TC_05.21 | C30: Medium | D30: Kiểm tra hiển thị thông báo lỗi khi mất kết nối/lỗi máy chủ | E30: 1. Đã đăng nhập, có quyền xem. 2. Hệ thống mạng bị ngắt hoặc máy chủ trả về lỗi 5xx. | F30: 1. Truy cập menu Nội dung hiển thị. 2. Chọn Gói bán. 3. Quan sát thông báo hiển thị trên màn hình. | G30: Hệ thống hiển thị thông báo: 'Không thể tải dữ liệu. Vui lòng thử lại sau'. Không hiển thị dữ liệu lỗi.
B31: TẠO MỚI NỘI DUNG GÓI BÁN
B32: =IF(F32="","",$D$3&"."&COUNTA($F$9:F32)&"") -> TC_05.22 | C32: High | D32: Kiểm tra truy cập màn hình Tạo mới khi không có quyền | E32: 1. Đã đăng nhập. 2. Tài khoản KHÔNG có quyền 'Tạo mới nội dung Gói bán'. | F32: 1. Truy cập menu Product Hub → Gói bán. 2. Nhấn '+ Tạo mới'. | G32: Hệ thống hiển thị thông báo lỗi phân quyền. Không điều hướng đến màn hình Tạo mới.
A33: AI | B33: =IF(F33="","",$D$3&"."&COUNTA($F$9:F33)&"") -> TC_05.23 | C33: High | D33: Kiểm tra giao diện màn hình Tạo mới - hiển thị đủ các trường theo v1.2 | E33: 1. Đã đăng nhập, có quyền tạo mới. 2. Hệ thống có ít nhất 1 Gói bán hoạt động và đã có giá bán. | F33: 1. Truy cập menu Product Hub → Gói bán. 2. Nhấn '+ Tạo mới'. 3. Quan sát giao diện form. | G33: Form Tạo mới hiển thị đầy đủ theo v1.2: - Dropdown Gói bán (bắt buộc) - Dropdown Kênh bán (bắt buộc, multi-select) - Bảng line items: Sản phẩm (SKU), Tên hiển thị trên kênh, Phương thức hiển thị, Sản phẩm nhận trong gói (checkbox), Hình ảnh SKU nhận trong gói - Tên hiển thị trên kênh (cấp Gói bán) - Icon gói bán (upload JPG/PNG/SVG <=1MB) - Mô tả card gói (text, không bắt buộc) - Mô tả ngắn gói bán (text editor, max 2000 ký tự) - Mô tả dài gói bán (text editor, max 12000 ký tự) - Ảnh gói bán (JPG/PNG <=1MB, max 10 ảnh) - Đặc tính gói bán (section read-only, load từ cấu hình) - Block Đặc quyền (Collapse/Expand) - Link video gói bán (URL http/https, không bắt buộc) - Hình ảnh banner đầu trang (max 10 JPG/PNG) - Hình ảnh banner giữa trang (bảng: STT/Ảnh/Hoạt động/Xóa) - Button Lưu, Button Hủy
B34: =IF(F34="","",$D$3&"."&COUNTA($F$9:F34)&"") -> TC_05.24 | C34: High | D34: Kiểm tra Dropdown Gói bán chỉ load gói bán đang hoạt động và đã có giá bán | E34: 1. Đã đăng nhập, có quyền tạo mới. 2. Hệ thống có: (A) gói hoạt động + có giá; (B) gói bị tắt; (C) gói hoạt động nhưng chưa có giá. | F34: 1. Truy cập Tạo mới. 2. Mở dropdown 'Gói bán'. 3. Quan sát danh sách. | G34: Chỉ hiển thị gói loại (A). Gói (B) không xuất hiện.
B35: =IF(F35="","",$D$3&"."&COUNTA($F$9:F35)&"") -> TC_05.25 | C35: High | D35: Kiểm tra validate bắt buộc trường Gói bán khi để trống | E35: Đã đăng nhập, có quyền tạo mới. | F35: 1. Mở màn hình Tạo mới. 2. Không chọn Gói bán. 3. Nhấn 'Lưu'. | G35: Hệ thống hiển thị thông báo. Dữ liệu không được lưu.
B36: =IF(F36="","",$D$3&"."&COUNTA($F$9:F36)&"") -> TC_05.26 | C36: Medium | D36: Kiểm tra Gói bán là Single select | E36: 1. Đã đăng nhập, có quyền tạo mới. 2. Hệ thống có ít nhất 2 gói bán hợp lệ. | F36: 1. Mở màn hình Tạo mới. 2. Chọn Gói bán A. 3. Đổi sang Gói bán B. 4. Quan sát dropdown. | G36: Chỉ Gói bán B được chọn. Dropdown hiển thị đúng 1 giá trị.
B37: =IF(F37="","",$D$3&"."&COUNTA($F$9:F37)&"") -> TC_05.27 | C37: High | D37: Kiểm tra Kênh bán load động theo Gói bán đã chọn (BR-C03) | E37: 1. Đã đăng nhập, có quyền tạo mới. 2. Gói bán X chỉ áp dụng cho FPT.vn. | F37: 1. Mở màn hình Tạo mới. 2. Chọn Gói bán X. 3. Mở dropdown Kênh bán. 4. Quan sát danh sách. | G37: Dropdown Kênh bán chỉ hiển thị FPT.vn (load đúng theo Gói bán đã chọn).
B38: =IF(F38="","",$D$3&"."&COUNTA($F$9:F38)&"") -> TC_05.28 | C38: High | D38: Kiểm tra validate bắt buộc trường Kênh bán khi để trống | E38: 1. Đã đăng nhập, có quyền tạo mới. 2. Đã chọn Gói bán hợp lệ. | F38: 1. Mở màn hình Tạo mới. 2. Chọn Gói bán. 3. Không chọn Kênh bán. 4. Nhấn 'Lưu'. | G38: Hệ thống hiển thị thông báo lỗi validation tại trường Kênh bán. Dữ liệu không được lưu.
A39: AI | B39: =IF(F39="","",$D$3&"."&COUNTA($F$9:F39)&"") -> TC_05.29 | C39: Medium | D39: Kiểm tra Kênh bán Multi-select - chọn nhiều kênh cùng lúc [V1.2] | E39: 1. Đã đăng nhập, có quyền tạo mới. 2. Gói bán có nhiều kênh hợp lệ (FPT.vn, tongdaiwifi.vn). | F39: 1. Mở màn hình Tạo mới. 2. Chọn Gói bán. 3. Chọn Kênh bán A (FPT.vn). 4. Chọn thêm Kênh bán B (tongdaiwifi.vn). 5. Quan sát dropdown Kênh bán. | G39: Cả Kênh bán A và B đều được chọn và hiển thị. Hệ thống cho phép multi-select. Không deselect kênh khi chọn thêm.
B40: =IF(F40="","",$D$3&"."&COUNTA($F$9:F40)&"") -> TC_05.30 | C40: High | D40: Kiểm tra reset Kênh bán khi thay đổi Gói bán (BR-C04) | E40: 1. Đã đăng nhập, có quyền tạo mới. 2. Đã chọn Gói bán A và Kênh bán tương ứng. | F40: 1. Mở màn hình Tạo mới. 2. Chọn Gói bán A. 3. Chọn Kênh bán. 4. Thay đổi sang Gói bán B. 5. Quan sát dropdown Kênh bán. | G40: Kênh bán bị reset về trạng thái trống sau khi thay đổi Gói bán.
B41: =IF(F41="","",$D$3&"."&COUNTA($F$9:F41)&"") -> TC_05.31 | C41: High | D41: Kiểm tra bảng line items - hiển thị đủ 5 cột theo v1.1 | E41: 1. Đã đăng nhập, có quyền tạo mới. 2. Đã chọn Gói bán hợp lệ. | F41: 1. Mở màn hình Tạo mới. 2. Chọn Gói bán. 3. Quan sát bảng line items. | G41: Bảng hiển thị đủ 5 cột: 1. Sản phẩm (SKU) - read-only 2. Tên hiển thị trên kênh - input text 3. Phương thức hiển thị - dropdown 4. Sản phẩm nhận trong gói - checkbox 5. Hình ảnh SKU nhận trong gói - image upload
B42: =IF(F42="","",$D$3&"."&COUNTA($F$9:F42)&"") -> TC_05.32 | C42: High | D42: Kiểm tra auto-fill 'Tên hiển thị trên kênh' (cột bảng) sau khi chọn Gói bán - SKU đơn | E42: 1. Đã đăng nhập, có quyền tạo mới. 2. Gói bán Z có SKU đơn với Display name = 'SKU_Name_A'. | F42: 1. Mở màn hình Tạo mới. 2. Chọn Gói bán Z. 3. Quan sát cột 'Tên hiển thị trên kênh' trong bảng. | G42: Cột 'Tên hiển thị trên kênh' tự động điền 'SKU_Name_A' (Display name của SKU).
B43: =IF(F43="","",$D$3&"."&COUNTA($F$9:F43)&"") -> TC_05.33 | C43: High | D43: Kiểm tra auto-fill 'Tên hiển thị trên kênh' (cột bảng) - Phí đi kèm | E43: 1. Đã đăng nhập, có quyền tạo mới. 2. Gói bán Q có line item Phí đi kèm với Name = 'Phí lắp đặt'. | F43: 1. Mở màn hình Tạo mới. 2. Chọn Gói bán Q. 3. Quan sát cột 'Tên hiển thị trên kênh' trong bảng. | G43: Cột 'Tên hiển thị trên kênh' tự động điền 'Phí lắp đặt' (Name của Phí đi kèm).
B44: =IF(F44="","",$D$3&"."&COUNTA($F$9:F44)&"") -> TC_05.34 | C44: High | D44: Kiểm tra validate bắt buộc 'Tên hiển thị trên kênh' (cột bảng) khi xóa trắng | E44: 1. Đã đăng nhập, có quyền tạo mới. 2. Đã chọn Gói bán, Kênh bán. | F44: 1. Mở màn hình Tạo mới. 2. Chọn Gói bán, Kênh bán. 3. Xóa nội dung trường 'Tên hiển thị trên kênh' trong bảng. 4. Nhấn 'Lưu'. | G44: Hệ thống hiển thị thông báo lỗi validation tại trường 'Tên hiển thị trên kênh'. Dữ liệu không được lưu.
...

Sheet Thông tin chung
A3: Mã chức năng (Function ID) | C3: TC_01
A4: Tên chức năng (Function Name) | C4: Thông tin chung
A7: Testcase ID | B7: Mức Độ Ưu Tiên (Priority) | C7: Nội Dung Test (Test Title) | D7: Điều Kiện/ Dữ Liệu Test (Pre-condition/ Test Data) | E7: Các Bước Thực Hiện (Test Steps) | F7: Kết Quả Mong Đợi (Expected Results) | G7: =Summary!G8 -> Round 1 (09/04/2026 - 15/04/2026) | M7: =Summary!L8 -> Round 2 (dd/mm/yyyy - dd/mm/yyyy) | Q7: =Summary!Q8 -> Round 3(dd/mm/yyyy - dd/mm/yyyy) | U7: =Summary!V8 -> Round 4 (dd/mm/yyyy - dd/mm/yyyy)
G8: Kết Quả Thực Hiện (Actual Result) | J8: Người Thực Hiện (Executed By) | K8: ID Bugs | L8: Ghi Chú (Remark) | M8: Kết Quả Thực Hiện (Actual Result) | N8: Người Thực Hiện (Executed By) | O8: ID Bugs | P8: Ghi Chú (Remark) | Q8: Kết Quả Thực Hiện (Actual Result) | R8: Người Thực Hiện (Executed By) | S8: ID Bugs | T8: Ghi Chú (Remark) | U8: Kết Quả Thực Hiện (Actual Result) | V8: Người Thực Hiện (Executed By) | W8: ID Bugs | X8: Ghi Chú (Remark)
A9: Các dịch vụ cần test | G9: AP | H9: Smart Home | I9: Smart Tivi
A10: Màn hình nhập thông tin
A11: Màn hình nhập thông tin - Header
A12: =IF(E12="","",$C$3&"."&COUNTA($E$12:E12)&"") -> TC_01.1 | B12: Medium | C12: Click vào Logo FPT Telecom | D12: - Đang ở màn hình nhập thông tin đăng ký/thanh toán | E12: 1. Click vào logo FPT Telecom | F12: - Truy cập link trực tiếp: Điều hướng vào màn hình Home fpt.vn - Truy cập từ tongdaiwifi: Điều hướng về home https://staging.tongdaiwifi.vn/
A13: =IF(E13="","",$C$3&"."&COUNTA($E$12:E13)&"") -> TC_01.2 | B13: Medium | C13: Click vào icon back_ từ Home truy cập trực tiếp link | D13: - Có link đăng ký dịch vụ | E13: 1. Mở trình duyệt 2. Truy cập trực tiếp link đăng ký dịch vụ 3. Click vào icon back | F13: Điều hướng vào màn hình Home fpt.vn
A14: =IF(E14="","",$C$3&"."&COUNTA($E$12:E14)&"") -> TC_01.3 | B14: Medium | C14: Click vào icon back_ từ Home tongdaiwifi.vn | D14: - Đang ở màn hình nhập thông tin đăng ký/thanh toán | E14: 1. Mở trình duyệt 2. Truy cập trang tongdaiwifi.vn 3. Click btn Đăng ký ngay 4. Click vào icon back | F14: Điều hướng về home https://staging.tongdaiwifi.vn/
A15: Màn hình nhập thông tin - Tiến trình các bước
A16: =IF(E16="","",$C$3&"."&COUNTA($E$12:E16)&"") -> TC_01.4 | B16: Medium | C16: Check màu sắc mặc định tại các bước | D16: - Đang ở màn hình nhập thông tin đăng ký/thanh toán | E16: 1. Quan sát màu sắc tại các bước tiến trình. | F16: Hiển thị đúng màu sắc mặc định tại các bước. Gồm: + Bước 1: màu xanh dương + Bước 2,3: màu xám
A17: =IF(E17="","",$C$3&"."&COUNTA($E$12:E17)&"") -> TC_01.5 | B17: Medium | C17: Click vào các bước 1,2,3 khi đang ở bước 1 | D17: - Đang ở màn hình nhập thông tin đăng ký/thanh toán - Đang ở bước 1 | E17: 1. Click vào icon của các bước 1,2,3 | F17: Không có action nào, vẫn ở màn hình hiện tại
A18: =IF(E18="","",$C$3&"."&COUNTA($E$12:E18)&"") -> TC_01.6 | B18: Medium | C18: Click vào bước 1 khi đang ở bước 2 | D18: - Đang ở màn hình nhập thông tin đăng ký/thanh toán - Hiển thị tiến trình 3 bước - Đang ở bước 2 | E18: 1. Click vào icon của bước 1 | F18: Cho phép quay về bước 1 khi click vào icon bước 1
A19: Màn hình nhập thông tin - Block Sản phẩm dịch vụ đã chọn
A20: =IF(E20="","",$C$3&"."&COUNTA($E$9:E20)&"") -> TC_01.7 | B20: Medium | C20: Check load Số lượng gói dịch vụ | D20: Chọn 1 gói dịch vụ SA ở màn hình Chi tiết dịch vụ | E20: 1. Truy cập màn hình Thanh toán dịch vụ 2. Tại block Sản phẩm dịch vụ đã chọn 3. Check load Số lượng gói dịch vụ | F20: Hiển thị đúng số lượng gói dịch vụ đã chọn
A21: =IF(E21="","",$C$3&"."&COUNTA($E$9:E21)&"") -> TC_01.8 | B21: Medium | C21: Check load data Gói dịch vụ | D21: Chọn 1 gói dịch vụ SA ở màn hình Chi tiết dịch vụ | E21: 1. Truy cập màn hình Thanh toán dịch vụ 2. Tại block Sản phẩm dịch vụ đã chọn 3. Check hiển thị các trường trong block Sản phẩm dịch vụ đã chọn | F21: Hệ thống hiển thị lại gói khách hàng đã chọn
A22: =IF(E22="","",$C$3&"."&COUNTA($E$9:E22)&"") -> TC_01.9 | B22: Medium | C22: Check load Chu kỳ gói dịch vụ | D22: Chọn 1 gói dịch vụ SA ở màn hình Chi tiết dịch vụ | E22: 1. Truy cập màn hình Thanh toán dịch vụ 2. Tại block Sản phẩm dịch vụ đã chọn 3. Check load Chu kỳ gói dịch vụ | F22: Hệ thống hiển thị đúng chu kỳ đã chọn, ví dụ: 3 tháng, 6 tháng, 12 tháng.
A23: =IF(E23="","",$C$3&"."&COUNTA($E$9:E23)&"") -> TC_01.10 | B23: Medium | C23: Check load Giá gói dịch vụ | D23: Chọn 1 gói dịch vụ SA ở màn hình Chi tiết dịch vụ | E23: 1. Truy cập màn hình Thanh toán dịch vụ 2. Tại block Sản phẩm dịch vụ đã chọn 3. Check load Giá gói dịch vụ | F23: Hệ thống hiển thị giá của gói đã chọn. Nếu có ưu đãi, hệ thống hiển thị giá sau ưu đãi.
A24: =IF(E24="","",$C$3&"."&COUNTA($E$9:E24)&"") -> TC_01.11 | B24: Medium | C24: Check load icon Gói dịch vụ | D24: Chọn 1 gói dịch vụ SA ở màn hình Chi tiết dịch vụ | E24: 1. Truy cập màn hình Thanh toán dịch vụ 2. Tại block Sản phẩm dịch vụ đã chọn 3. Check icon Gói dịch vụ | F24: Hiển thị đúng hình ảnh theo config Product Hub
A25: Màn hình nhập thông tin - Block Thông tin Cá nhân
B26: Họ Tên (NET, ComBo Net)
B27: Medium | C27: Check khung viền màu xanh khi click chuột vào các trường Họ tên | D27: - Đang ở màn hình nhập thông tin đăng ký/thanh toán - Đang đăng ký dịch vụ NET/Combo net | E27: 1. Click vào trường Họ tên 2. Check hiển thị viền xanh | F27: Hiển thị viền màu xanh của trường
B28: Medium | C28: Check btn x trong trường Họ tên | D28: - Đang ở màn hình nhập thông tin đăng ký/thanh toán - Đang đăng ký dịch vụ NET/Combo net | E28: 1. Nhập 1 ký tự bất kỳ tại trường Họ tên 2. Check hiển thị icon x | F28: Hiển thị icon X khi nhập ký tự bất kỳ
B29: Medium | C29: Click btn x trong trường Họ tên | D29: - Đang ở màn hình nhập thông tin đăng ký/thanh toán - Đang đăng ký dịch vụ NET/Combo net | E29: 1. Nhập 1 ký tự bất kỳ tại trường Họ tên 2. Click icon x | F29: Xóa toàn bộ kí tự trong trường Họ tên và ẩn icon X
B30: Medium | C30: Check trường Họ tên để trống | D30: - Đang ở màn hình nhập thông tin đăng ký/thanh toán - Đang đăng ký dịch vụ NET/Combo net | E30: 1. Click vào trường Họ tên và không nhập data 2. Click ra ngoài trường Họ tên | F30: Border đỏ trường họ tên và thông báo " Vui lòng nhập họ và tên."
B31: Medium | C31: Check trường Họ tên nhập khoảng trắng | D31: - Đang ở màn hình nhập thông tin đăng ký/thanh toán - Đang đăng ký dịch vụ NET/Combo net | E31: 1. Click vào trường Họ tên 2. Nhập khoảng trắng 3. Click ra ngoài trường Họ tên | F31: Border đỏ trường họ tên và thông báo " Vui lòng nhập họ và tên."
B32: Medium | C32: Check nhập Họ tên có khoảng trắng đầu cuối | D32: - Đang ở màn hình nhập thông tin đăng ký/thanh toán - Đang đăng ký dịch vụ NET/Combo net | E32: 1. Nhập Họ tên có khoảng trắng đầu cuối 2. Nhập các trường bắt buộc khác 3. Btn Tiếp tục | F32: Cho phép qua màn hình tiếp theo không báo lỗi (khi submit sẽ trim khoảng trắng đi)
B33: Medium | C33: Check nhập hoặc copy-paste Họ tên có ký tự đặc biệt', số | D33: - Đang ở màn hình nhập thông tin đăng ký/thanh toán - Đang đăng ký dịch vụ NET/Combo net | E33: 1. Nhập/copy-paste họ tên có ký tự đặc biệt 2. Nhập các trường bắt buộc khác 3. Btn Tiếp tục | F33: Hiển thị thông báo "Họ tên không hợp lệ" * chỉ được nhận chữ + khoảng trắng
B34: Medium | C34: Check nhập/copy-paste Họ tên > 100 ký tự | D34: - Đang ở màn hình nhập thông tin đăng ký/thanh toán - Đang đăng ký dịch vụ NET/Combo net | E34: 1. Nhập/copy-paste Họ tên > 100 ký tự | F34: Chỉ cho phép nhập và hiển thị 100 ký tự
B35: Số điện thoại (Tất cả dịch vụ)
A36: =IF(E36="","",$C$3&"."&COUNTA($E$9:E36)&"") -> TC_01.20 | B36: Medium | C36: Check btn x trong trường Số điện thoại | D36: - Đang ở màn hình nhập thông tin đăng ký/thanh toán - Đang đăng ký dịch vụ bất kỳ | E36: 1. Nhập 1 số bất kỳ tại trường Số điện thoại 2. Check hiển thị icon x | F36: Hiển thị icon X khi nhập ký tự bất kỳ
A37: =IF(E37="","",$C$3&"."&COUNTA($E$12:E37)&"") -> TC_01.21 | B37: Medium | C37: Click btn x trong trường số điện thoại | D37: - Đang ở màn hình nhập thông tin đăng ký/thanh toán - Đang đăng ký dịch vụ bất kỳ | E37: 1. Nhập số bất kỳ tại trường Số điện thoại 2. Click icon x | F37: Xóa toàn bộ kí tự trong trường Số điện thoại và ẩn icon X
A38: =IF(E38="","",$C$3&"."&COUNTA($E$12:E38)&"") -> TC_01.22 | B38: Medium | C38: Check trường Số điện thoại để trống | D38: - Đang ở màn hình nhập thông tin đăng ký/thanh toán - Đang đăng ký dịch vụ bất kỳ | E38: 1. Click vào trường Số điện thoại và không nhập data 2. Click ra ngoài trường Số điện thoại | F38: Border đỏ trường số điện thoại và thông báo "Vui lòng nhập số điện thoại."
