Workbook
Name Testing_status: #REF!
Name Testing_status: #REF!
Name Testing_status: #REF!
Name Testing_status: #REF!
Name Testing_status: #REF!
Name Display_Week: #REF!
Name Project_Start: #REF!

Sheet Cover
B6: ECP
B7: TESTCASE
F9: Mã hiệu
F10: Phiên bản | I10: 1.0
F11: Ngày hiệu lực

Sheet Revision history
C1: REVISION HISTORY - TESTCASE
B4: Phiên bản testcase (Testcase version) | C4: Ngày cập nhật (Date Update) | D4: Người tạo (Author) | E4: Người xem xét (Reviewer) | F4: Tên chức năng (Function name) | G4: Mô tả chức năng (Function description) | H4: Tình trạng (Status)
B5: v1.0
B6: v1.0_Sprint 10 | C6: 20/03/2026 | D6: GiangDC2, AnhDC4 | E6: HuyenNHK | F6: Luồng checkout Net,Combo net | G6: Luồng checkout Net,Combo net | H6: Thêm mới
B7: v1.0 Sprint 12 | C7: 46026 | D7: GiangDC2, AnhDC4 | E7: HuyenNHK | F7: Thông tin chung | G7: Các TC dùng chung cho tất cả dịch vụ (UI, navigation, form validation cơ bản...) | H7: Thêm mới
F8: FPL SA | G8: Luồng checkout FPL SA | H8: Thêm mới
F9: Ultra Fast | G9: Luồng checkout Ultra Fast | H9: Thêm mới
F10: Hyper Fast | G10: Luồng checkout Hyper Fast | H10: Thêm mới
F11: Chi tiết các dịch vụ SA | G11: Chi tiết các dịch vụ SA(FPTPlay, UltraFast, HyperFast) | H11: Thêm mới
F12: Trang tổng hợp dịch vụ | G12: Trang tổng hợp dịch vụ số (UltraFast, HyperFast) | H12: Thêm mới
C29: REVISION HISTORY - TEMPLATE
B30: [Phần này chỉ giành cho QA update]
B32: Ngày hiệu lực | C32: Version | D32: Người tạo | E32: Người xem xét | F32: Người phê duyệt | G32: Nội dung thay đổi
C33: 1.0 | G33: Tạo mới

Sheet Guideline
B3: QUY ĐỊNH CHUNG
B4: 1. Tên File Testcase/Report đặt theo chuẩn:
B5: ISC_[Tên Dự Án]_[Version Dự Án]_TC_[Version File TC theo Revision history]_R[Số vòng test khi report].xlsx
B6: ISC_[Tên Dự Án]_[Version Dự Án]_Report.xlsx
B7: VD: ISC_Salary FTI_V2.2_TC_V1.0_R1.xlsx ISC_Salary FTI_V2.2_Report.xlsx
B8: 2. Khi update nội dung File Testcase (Add/Update/Delete các Function/Screen) phải tăng [Version File TC] và quản lý lịch sử thay đổi trong Revision history.
B9: 3. Các Function/ Screen khác nhau được tách ra thành từng sheet.
B10: - [Nội Dung Test/Test Title] trongTestcase tách ra từng case riêng biệt không gộp lại thành 1 case nhưng kết quả test khác nhau.
B11: - [Người thực hiện]: sử dụng tên email, chỉ duy nhất một người thực hiện.
B13: BẢNG PHÂN LOẠI TRẠNG THÁI TESTCASE
B15: Trạng thái | C15: Ý nghĩa
B16: (Blank) | C16: Trạng thái mặc định khi chưa thực hiện test
B17: Pass | C17: Thực hiện thành công case
B18: Fail | C18: Không thành công case, có lỗi phát sinh
B19: Block | C19: Case này không thể thực hiện/Pending, ghi rõ lý do trong phần ghi chú: (VD: Do chưa dev xong, Không có điều kiện - dữ liệu test, Tài liệu đặc tả sai, Đã thay đổi yêu cầu...).
B20: N/A | C20: - Case Suggest - Case Won't fix
B23: BẢNG PHÂN LOẠI ĐỘ ƯU TIÊN
B25: Trạng thái | C25: Ý nghĩa
B26: High | C26: - Phải thực hiện trong bất kỳ vòng nào - Case ảnh hưởng trực tiếp đến nhiều người dùng - Chức năng, nghiệp vụ
B27: Medium | C27: - Phải thực hiện ít nhất một lần - Ảnh hưởng đến người dùng
B28: Low | C28: - Có thể bỏ qua khi rút ngắn thời gian test - Case không gây ảnh hưởng nhiều đến người dùng - Case phụ thêm - Không quy định trong tài liệu

Sheet Summary
D1: SUMMARY
A5: Project name | C5: ECP | D5: Version | E5: V1.0 - Sprint 12
A6: Division | C6: ECOM | D6: Project Manager - PM | E6: TaiTT13
B8: STT | C8: Mã chức năng | D8: Sheet Name | E8: Function/ Screen | F8: Số Testcase | G8: Round 1 (09/04/2026 - 15/04/2026) | K8: G:I | L8: Round 2 (dd/mm/yyyy - dd/mm/yyyy) | P8: K:K | Q8: Round 3(dd/mm/yyyy - dd/mm/yyyy) | U8: O:O | V8: Round 4 (dd/mm/yyyy - dd/mm/yyyy) | Z8: S:S | AA8: Round 5 (dd/mm/yyyy - dd/mm/yyyy) | AE8: W:W | AF8: Round 6 (dd/mm/yyyy - dd/mm/yyyy) | AJ8: AA:AA | AK8: Round 7 (dd/mm/yyyy - dd/mm/yyyy) | AO8: AE:AE | AP8: Round 8 (dd/mm/yyyy - dd/mm/yyyy) | AT8: AI:AI | AU8: Round 9 (dd/mm/yyyy - dd/mm/yyyy) | AY8: AM:AM | AZ8: Round 10 (dd/mm/yyyy - dd/mm/yyyy) | BD8: AQ:AQ
G9: Excute Testcase | H9: Pass | I9: Fail | J9: N/A | K9: Block | L9: Excute Testcase | M9: Pass | N9: Fail | O9: N/A | P9: Block | Q9: Excute Testcase | R9: Pass | S9: Fail | T9: N/A | U9: Block | V9: Excute Testcase | W9: Pass | X9: Fail | Y9: N/A | Z9: Block | AA9: Excute Testcase | AB9: Pass | AC9: Fail | AD9: N/A | AE9: Block | AF9: Excute Testcase | AG9: Pass | AH9: Fail | AI9: N/A | AJ9: Block | AK9: Excute Testcase | AL9: Pass | AM9: Fail | AN9: N/A | AO9: Block | AP9: v | AQ9: Pass | AR9: Fail | AS9: N/A | AT9: Block | AU9: Excute Testcase | AV9: Pass | AW9: Fail | AX9: N/A | AY9: Block | AZ9: Excute Testcase | BA9: Pass | BB9: Fail | BC9: N/A | BD9: Block
B10: 1 | C10: TC_01 | D10: Thông tin chung | E10: Thông tin chung | F10: 300 | G10: =SUM(H10:J10) -> 255 | H10: =COUNTIF(INDIRECT("'"&$D10&"'!"&K$8),"Pass") -> 255 | I10: =COUNTIF(INDIRECT("'"&$D10&"'!"&K$8),"Fail") -> 0 | J10: =COUNTIF(INDIRECT("'"&$D10&"'!"&K$8),"N/A") -> 0 | K10: =COUNTIF(INDIRECT("'"&$D10&"'!"&K$8),"Block") -> 45 | L10: =SUM(M10:O10) -> 0 | M10: =COUNTIF(INDIRECT("'"&$D10&"'!"&P$8),"Pass") -> 0 | N10: =COUNTIF(INDIRECT("'"&$D10&"'!"&P$8),"Fail") -> 0 | O10: =COUNTIF(INDIRECT("'"&$D10&"'!"&P$8),"N/A") -> 0 | P10: =COUNTIF(INDIRECT("'"&$D10&"'!"&P$8),"Block") -> 0 | Q10: =SUM(R10:T10) -> 0 | R10: =COUNTIF(INDIRECT("'"&$D10&"'!"&U$8),"Pass") -> 0 | S10: =COUNTIF(INDIRECT("'"&$D10&"'!"&U$8),"Fail") -> 0 | T10: =COUNTIF(INDIRECT("'"&$D10&"'!"&U$8),"N/A") -> 0 | U10: =COUNTIF(INDIRECT("'"&$D10&"'!"&U$8),"Block") -> 0 | V10: =SUM(W10:Y10) -> 0 | W10: =COUNTIF(INDIRECT("'"&$D10&"'!"&Z$8),"Pass") -> 0 | X10: =COUNTIF(INDIRECT("'"&$D10&"'!"&Z$8),"Fail") -> 0 | Y10: =COUNTIF(INDIRECT("'"&$D10&"'!"&Z$8),"N/A") -> 0 | Z10: =COUNTIF(INDIRECT("'"&$D10&"'!"&Z$8),"Block") -> 0 | AA10: =SUM(AB10:AD10) -> 0 | AB10: =COUNTIF(INDIRECT("'"&$D10&"'!"&AE$8),"Pass") -> 0 | AC10: =COUNTIF(INDIRECT("'"&$D10&"'!"&AE$8),"Fail") -> 0 | AD10: =COUNTIF(INDIRECT("'"&$D10&"'!"&AE$8),"N/A") -> 0 | AE10: =COUNTIF(INDIRECT("'"&$D10&"'!"&AE$8),"Block") -> 0 | AF10: =SUM(AG10:AI10) -> 0 | AG10: =COUNTIF(INDIRECT("'"&$D10&"'!"&AJ$8),"Pass") -> 0 | AH10: =COUNTIF(INDIRECT("'"&$D10&"'!"&AJ$8),"Fail") -> 0 | AI10: =COUNTIF(INDIRECT("'"&$D10&"'!"&AJ$8),"N/A") -> 0 | AJ10: =COUNTIF(INDIRECT("'"&$D10&"'!"&AJ$8),"Block") -> 0 | AK10: =SUM(AL10:AN10) -> 0 | AL10: =COUNTIF(INDIRECT("'"&$D10&"'!"&AO$8),"Pass") -> 0 | AM10: =COUNTIF(INDIRECT("'"&$D10&"'!"&AO$8),"Fail") -> 0 | AN10: =COUNTIF(INDIRECT("'"&$D10&"'!"&AO$8),"N/A") -> 0 | AO10: =COUNTIF(INDIRECT("'"&$D10&"'!"&AO$8),"Block") -> 0 | AP10: =SUM(AQ10:AS10) -> 0 | AQ10: =COUNTIF(INDIRECT("'"&$D10&"'!"&AT$8),"Pass") -> 0 | AR10: =COUNTIF(INDIRECT("'"&$D10&"'!"&AT$8),"Fail") -> 0 | AS10: =COUNTIF(INDIRECT("'"&$D10&"'!"&AT$8),"N/A") -> 0 | AT10: =COUNTIF(INDIRECT("'"&$D10&"'!"&AT$8),"Block") -> 0 | AU10: =SUM(AV10:AX10) -> 0 | AV10: =COUNTIF(INDIRECT("'"&$D10&"'!"&AY$8),"Pass") -> 0 | AW10: =COUNTIF(INDIRECT("'"&$D10&"'!"&AY$8),"Fail") -> 0 | AX10: =COUNTIF(INDIRECT("'"&$D10&"'!"&AY$8),"N/A") -> 0 | AY10: =COUNTIF(INDIRECT("'"&$D10&"'!"&AY$8),"Block") -> 0 | AZ10: =SUM(BA10:BC10) -> 0 | BA10: =COUNTIF(INDIRECT("'"&$D10&"'!"&BD$8),"Pass") -> 0 | BB10: =COUNTIF(INDIRECT("'"&$D10&"'!"&BD$8),"Fail") -> 0 | BC10: =COUNTIF(INDIRECT("'"&$D10&"'!"&BD$8),"N/A") -> 0 | BD10: =COUNTIF(INDIRECT("'"&$D10&"'!"&BD$8),"Block") -> 0
B11: 2 | C11: TC_02 | D11: FPL SA | E11: FPL SA | F11: =COUNTIF(INDIRECT("'"&D11&"'!A:A"),C11&"*") -> 22 | G11: =SUM(H11:J11) -> 17 | H11: =COUNTIF(INDIRECT("'"&$D11&"'!"&K$8),"Pass") -> 16 | I11: =COUNTIF(INDIRECT("'"&$D11&"'!"&K$8),"Fail") -> 0 | J11: =COUNTIF(INDIRECT("'"&$D11&"'!"&K$8),"N/A") -> 1 | K11: =COUNTIF(INDIRECT("'"&$D11&"'!"&K$8),"Block") -> 5 | L11: =SUM(M11:O11) -> 0 | M11: =COUNTIF(INDIRECT("'"&$D11&"'!"&P$8),"Pass") -> 0 | N11: =COUNTIF(INDIRECT("'"&$D11&"'!"&P$8),"Fail") -> 0 | O11: =COUNTIF(INDIRECT("'"&$D11&"'!"&P$8),"N/A") -> 0 | P11: =COUNTIF(INDIRECT("'"&$D11&"'!"&P$8),"Block") -> 0 | Q11: =SUM(R11:T11) -> 0 | R11: =COUNTIF(INDIRECT("'"&$D11&"'!"&U$8),"Pass") -> 0 | S11: =COUNTIF(INDIRECT("'"&$D11&"'!"&U$8),"Fail") -> 0 | T11: =COUNTIF(INDIRECT("'"&$D11&"'!"&U$8),"N/A") -> 0 | U11: =COUNTIF(INDIRECT("'"&$D11&"'!"&U$8),"Block") -> 0 | V11: =SUM(W11:Y11) -> 0 | W11: =COUNTIF(INDIRECT("'"&$D11&"'!"&Z$8),"Pass") -> 0 | X11: =COUNTIF(INDIRECT("'"&$D11&"'!"&Z$8),"Fail") -> 0 | Y11: =COUNTIF(INDIRECT("'"&$D11&"'!"&Z$8),"N/A") -> 0 | Z11: =COUNTIF(INDIRECT("'"&$D11&"'!"&Z$8),"Block") -> 0 | AA11: =SUM(AB11:AD11) -> 0 | AB11: =COUNTIF(INDIRECT("'"&$D11&"'!"&AE$8),"Pass") -> 0 | AC11: =COUNTIF(INDIRECT("'"&$D11&"'!"&AE$8),"Fail") -> 0 | AD11: =COUNTIF(INDIRECT("'"&$D11&"'!"&AE$8),"N/A") -> 0 | AE11: =COUNTIF(INDIRECT("'"&$D11&"'!"&AE$8),"Block") -> 0 | AF11: =SUM(AG11:AI11) -> 0 | AG11: =COUNTIF(INDIRECT("'"&$D11&"'!"&AJ$8),"Pass") -> 0 | AH11: =COUNTIF(INDIRECT("'"&$D11&"'!"&AJ$8),"Fail") -> 0 | AI11: =COUNTIF(INDIRECT("'"&$D11&"'!"&AJ$8),"N/A") -> 0 | AJ11: =COUNTIF(INDIRECT("'"&$D11&"'!"&AJ$8),"Block") -> 0 | AK11: =SUM(AL11:AN11) -> 0 | AL11: =COUNTIF(INDIRECT("'"&$D11&"'!"&AO$8),"Pass") -> 0 | AM11: =COUNTIF(INDIRECT("'"&$D11&"'!"&AO$8),"Fail") -> 0 | AN11: =COUNTIF(INDIRECT("'"&$D11&"'!"&AO$8),"N/A") -> 0 | AO11: =COUNTIF(INDIRECT("'"&$D11&"'!"&AO$8),"Block") -> 0 | AP11: =SUM(AQ11:AS11) -> 0 | AQ11: =COUNTIF(INDIRECT("'"&$D11&"'!"&AT$8),"Pass") -> 0 | AR11: =COUNTIF(INDIRECT("'"&$D11&"'!"&AT$8),"Fail") -> 0 | AS11: =COUNTIF(INDIRECT("'"&$D11&"'!"&AT$8),"N/A") -> 0 | AT11: =COUNTIF(INDIRECT("'"&$D11&"'!"&AT$8),"Block") -> 0 | AU11: =SUM(AV11:AX11) -> 0 | AV11: =COUNTIF(INDIRECT("'"&$D11&"'!"&AY$8),"Pass") -> 0 | AW11: =COUNTIF(INDIRECT("'"&$D11&"'!"&AY$8),"Fail") -> 0 | AX11: =COUNTIF(INDIRECT("'"&$D11&"'!"&AY$8),"N/A") -> 0 | AY11: =COUNTIF(INDIRECT("'"&$D11&"'!"&AY$8),"Block") -> 0 | AZ11: =SUM(BA11:BC11) -> 0 | BA11: =COUNTIF(INDIRECT("'"&$D11&"'!"&BD$8),"Pass") -> 0 | BB11: =COUNTIF(INDIRECT("'"&$D11&"'!"&BD$8),"Fail") -> 0 | BC11: =COUNTIF(INDIRECT("'"&$D11&"'!"&BD$8),"N/A") -> 0 | BD11: =COUNTIF(INDIRECT("'"&$D11&"'!"&BD$8),"Block") -> 0
B12: 3 | C12: TC_03 | D12: Ultra Fast | E12: Ultra Fast | F12: =COUNTIF(INDIRECT("'"&D12&"'!A:A"),C12&"*") -> 24 | G12: =SUM(H12:J12) -> 11 | H12: =COUNTIF(INDIRECT("'"&$D12&"'!"&K$8),"Pass") -> 11 | I12: =COUNTIF(INDIRECT("'"&$D12&"'!"&K$8),"Fail") -> 0 | J12: =COUNTIF(INDIRECT("'"&$D12&"'!"&K$8),"N/A") -> 0 | K12: =COUNTIF(INDIRECT("'"&$D12&"'!"&K$8),"Block") -> 13 | L12: =SUM(M12:O12) -> 0 | M12: =COUNTIF(INDIRECT("'"&$D12&"'!"&P$8),"Pass") -> 0 | N12: =COUNTIF(INDIRECT("'"&$D12&"'!"&P$8),"Fail") -> 0 | O12: =COUNTIF(INDIRECT("'"&$D12&"'!"&P$8),"N/A") -> 0 | P12: =COUNTIF(INDIRECT("'"&$D12&"'!"&P$8),"Block") -> 0 | Q12: =SUM(R12:T12) -> 0 | R12: =COUNTIF(INDIRECT("'"&$D12&"'!"&U$8),"Pass") -> 0 | S12: =COUNTIF(INDIRECT("'"&$D12&"'!"&U$8),"Fail") -> 0 | T12: =COUNTIF(INDIRECT("'"&$D12&"'!"&U$8),"N/A") -> 0 | U12: =COUNTIF(INDIRECT("'"&$D12&"'!"&U$8),"Block") -> 0 | V12: =SUM(W12:Y12) -> 0 | W12: =COUNTIF(INDIRECT("'"&$D12&"'!"&Z$8),"Pass") -> 0 | X12: =COUNTIF(INDIRECT("'"&$D12&"'!"&Z$8),"Fail") -> 0 | Y12: =COUNTIF(INDIRECT("'"&$D12&"'!"&Z$8),"N/A") -> 0 | Z12: =COUNTIF(INDIRECT("'"&$D12&"'!"&Z$8),"Block") -> 0 | AA12: =SUM(AB12:AD12) -> 0 | AB12: =COUNTIF(INDIRECT("'"&$D12&"'!"&AE$8),"Pass") -> 0 | AC12: =COUNTIF(INDIRECT("'"&$D12&"'!"&AE$8),"Fail") -> 0 | AD12: =COUNTIF(INDIRECT("'"&$D12&"'!"&AE$8),"N/A") -> 0 | AE12: =COUNTIF(INDIRECT("'"&$D12&"'!"&AE$8),"Block") -> 0 | AF12: =SUM(AG12:AI12) -> 0 | AG12: =COUNTIF(INDIRECT("'"&$D12&"'!"&AJ$8),"Pass") -> 0 | AH12: =COUNTIF(INDIRECT("'"&$D12&"'!"&AJ$8),"Fail") -> 0 | AI12: =COUNTIF(INDIRECT("'"&$D12&"'!"&AJ$8),"N/A") -> 0 | AJ12: =COUNTIF(INDIRECT("'"&$D12&"'!"&AJ$8),"Block") -> 0 | AK12: =SUM(AL12:AN12) -> 0 | AL12: =COUNTIF(INDIRECT("'"&$D12&"'!"&AO$8),"Pass") -> 0 | AM12: =COUNTIF(INDIRECT("'"&$D12&"'!"&AO$8),"Fail") -> 0 | AN12: =COUNTIF(INDIRECT("'"&$D12&"'!"&AO$8),"N/A") -> 0 | AO12: =COUNTIF(INDIRECT("'"&$D12&"'!"&AO$8),"Block") -> 0 | AP12: =SUM(AQ12:AS12) -> 0 | AQ12: =COUNTIF(INDIRECT("'"&$D12&"'!"&AT$8),"Pass") -> 0 | AR12: =COUNTIF(INDIRECT("'"&$D12&"'!"&AT$8),"Fail") -> 0 | AS12: =COUNTIF(INDIRECT("'"&$D12&"'!"&AT$8),"N/A") -> 0 | AT12: =COUNTIF(INDIRECT("'"&$D12&"'!"&AT$8),"Block") -> 0 | AU12: =SUM(AV12:AX12) -> 0 | AV12: =COUNTIF(INDIRECT("'"&$D12&"'!"&AY$8),"Pass") -> 0 | AW12: =COUNTIF(INDIRECT("'"&$D12&"'!"&AY$8),"Fail") -> 0 | AX12: =COUNTIF(INDIRECT("'"&$D12&"'!"&AY$8),"N/A") -> 0 | AY12: =COUNTIF(INDIRECT("'"&$D12&"'!"&AY$8),"Block") -> 0 | AZ12: =SUM(BA12:BC12) -> 0 | BA12: =COUNTIF(INDIRECT("'"&$D12&"'!"&BD$8),"Pass") -> 0 | BB12: =COUNTIF(INDIRECT("'"&$D12&"'!"&BD$8),"Fail") -> 0 | BC12: =COUNTIF(INDIRECT("'"&$D12&"'!"&BD$8),"N/A") -> 0 | BD12: =COUNTIF(INDIRECT("'"&$D12&"'!"&BD$8),"Block") -> 0
B13: 4 | C13: TC_04 | D13: Hyper Fast | E13: Hyper Fast | F13: =COUNTIF(INDIRECT("'"&D13&"'!A:A"),C13&"*") -> 40 | G13: =SUM(H13:J13) -> 13 | H13: =COUNTIF(INDIRECT("'"&$D13&"'!"&K$8),"Pass") -> 13 | I13: =COUNTIF(INDIRECT("'"&$D13&"'!"&K$8),"Fail") -> 0 | J13: =COUNTIF(INDIRECT("'"&$D13&"'!"&K$8),"N/A") -> 0 | K13: =COUNTIF(INDIRECT("'"&$D13&"'!"&K$8),"Block") -> 27 | L13: =SUM(M13:O13) -> 0 | M13: =COUNTIF(INDIRECT("'"&$D13&"'!"&P$8),"Pass") -> 0 | N13: =COUNTIF(INDIRECT("'"&$D13&"'!"&P$8),"Fail") -> 0 | O13: =COUNTIF(INDIRECT("'"&$D13&"'!"&P$8),"N/A") -> 0 | P13: =COUNTIF(INDIRECT("'"&$D13&"'!"&P$8),"Block") -> 0 | Q13: =SUM(R13:T13) -> 0 | R13: =COUNTIF(INDIRECT("'"&$D13&"'!"&U$8),"Pass") -> 0 | S13: =COUNTIF(INDIRECT("'"&$D13&"'!"&U$8),"Fail") -> 0 | T13: =COUNTIF(INDIRECT("'"&$D13&"'!"&U$8),"N/A") -> 0 | U13: =COUNTIF(INDIRECT("'"&$D13&"'!"&U$8),"Block") -> 0 | V13: =SUM(W13:Y13) -> 0 | W13: =COUNTIF(INDIRECT("'"&$D13&"'!"&Z$8),"Pass") -> 0 | X13: =COUNTIF(INDIRECT("'"&$D13&"'!"&Z$8),"Fail") -> 0 | Y13: =COUNTIF(INDIRECT("'"&$D13&"'!"&Z$8),"N/A") -> 0 | Z13: =COUNTIF(INDIRECT("'"&$D13&"'!"&Z$8),"Block") -> 0 | AA13: =SUM(AB13:AD13) -> 0 | AB13: =COUNTIF(INDIRECT("'"&$D13&"'!"&AE$8),"Pass") -> 0 | AC13: =COUNTIF(INDIRECT("'"&$D13&"'!"&AE$8),"Fail") -> 0 | AD13: =COUNTIF(INDIRECT("'"&$D13&"'!"&AE$8),"N/A") -> 0 | AE13: =COUNTIF(INDIRECT("'"&$D13&"'!"&AE$8),"Block") -> 0 | AF13: =SUM(AG13:AI13) -> 0 | AG13: =COUNTIF(INDIRECT("'"&$D13&"'!"&AJ$8),"Pass") -> 0 | AH13: =COUNTIF(INDIRECT("'"&$D13&"'!"&AJ$8),"Fail") -> 0 | AI13: =COUNTIF(INDIRECT("'"&$D13&"'!"&AJ$8),"N/A") -> 0 | AJ13: =COUNTIF(INDIRECT("'"&$D13&"'!"&AJ$8),"Block") -> 0 | AK13: =SUM(AL13:AN13) -> 0 | AL13: =COUNTIF(INDIRECT("'"&$D13&"'!"&AO$8),"Pass") -> 0 | AM13: =COUNTIF(INDIRECT("'"&$D13&"'!"&AO$8),"Fail") -> 0 | AN13: =COUNTIF(INDIRECT("'"&$D13&"'!"&AO$8),"N/A") -> 0 | AO13: =COUNTIF(INDIRECT("'"&$D13&"'!"&AO$8),"Block") -> 0 | AP13: =SUM(AQ13:AS13) -> 0 | AQ13: =COUNTIF(INDIRECT("'"&$D13&"'!"&AT$8),"Pass") -> 0 | AR13: =COUNTIF(INDIRECT("'"&$D13&"'!"&AT$8),"Fail") -> 0 | AS13: =COUNTIF(INDIRECT("'"&$D13&"'!"&AT$8),"N/A") -> 0 | AT13: =COUNTIF(INDIRECT("'"&$D13&"'!"&AT$8),"Block") -> 0 | AU13: =SUM(AV13:AX13) -> 0 | AV13: =COUNTIF(INDIRECT("'"&$D13&"'!"&AY$8),"Pass") -> 0 | AW13: =COUNTIF(INDIRECT("'"&$D13&"'!"&AY$8),"Fail") -> 0 | AX13: =COUNTIF(INDIRECT("'"&$D13&"'!"&AY$8),"N/A") -> 0 | AY13: =COUNTIF(INDIRECT("'"&$D13&"'!"&AY$8),"Block") -> 0 | AZ13: =SUM(BA13:BC13) -> 0 | BA13: =COUNTIF(INDIRECT("'"&$D13&"'!"&BD$8),"Pass") -> 0 | BB13: =COUNTIF(INDIRECT("'"&$D13&"'!"&BD$8),"Fail") -> 0 | BC13: =COUNTIF(INDIRECT("'"&$D13&"'!"&BD$8),"N/A") -> 0 | BD13: =COUNTIF(INDIRECT("'"&$D13&"'!"&BD$8),"Block") -> 0
B14: 5 | C14: TC_05 | D14: Chi tiết các dịch vụ SA | E14: Chi tiết các dịch vụ SA | F14: {=COUNTIF(INDIRECT("'"&D14&"'!A:A"),C14&"*")*3} -> 150 | G14: =SUM(H14:J14) -> 144 | H14: =COUNTIF(INDIRECT("'"&$D14&"'!"&K$8),"Pass") -> 144 | I14: =COUNTIF(INDIRECT("'"&$D14&"'!"&K$8),"Fail") -> 0 | J14: =COUNTIF(INDIRECT("'"&$D14&"'!"&K$8),"N/A") -> 0 | K14: =COUNTIF(INDIRECT("'"&$D14&"'!"&K$8),"Block") -> 6 | L14: =SUM(M14:O14) -> 0 | M14: =COUNTIF(INDIRECT("'"&$D14&"'!"&P$8),"Pass") -> 0 | N14: =COUNTIF(INDIRECT("'"&$D14&"'!"&P$8),"Fail") -> 0 | O14: =COUNTIF(INDIRECT("'"&$D14&"'!"&P$8),"N/A") -> 0 | P14: =COUNTIF(INDIRECT("'"&$D14&"'!"&P$8),"Block") -> 0 | Q14: =SUM(R14:T14) -> 0 | R14: =COUNTIF(INDIRECT("'"&$D14&"'!"&U$8),"Pass") -> 0 | S14: =COUNTIF(INDIRECT("'"&$D14&"'!"&U$8),"Fail") -> 0 | T14: =COUNTIF(INDIRECT("'"&$D14&"'!"&U$8),"N/A") -> 0 | U14: =COUNTIF(INDIRECT("'"&$D14&"'!"&U$8),"Block") -> 0 | V14: =SUM(W14:Y14) -> 0 | W14: =COUNTIF(INDIRECT("'"&$D14&"'!"&Z$8),"Pass") -> 0 | X14: =COUNTIF(INDIRECT("'"&$D14&"'!"&Z$8),"Fail") -> 0 | Y14: =COUNTIF(INDIRECT("'"&$D14&"'!"&Z$8),"N/A") -> 0 | Z14: =COUNTIF(INDIRECT("'"&$D14&"'!"&Z$8),"Block") -> 0 | AA14: =SUM(AB14:AD14) -> 0 | AB14: =COUNTIF(INDIRECT("'"&$D14&"'!"&AE$8),"Pass") -> 0 | AC14: =COUNTIF(INDIRECT("'"&$D14&"'!"&AE$8),"Fail") -> 0 | AD14: =COUNTIF(INDIRECT("'"&$D14&"'!"&AE$8),"N/A") -> 0 | AE14: =COUNTIF(INDIRECT("'"&$D14&"'!"&AE$8),"Block") -> 0 | AF14: =SUM(AG14:AI14) -> 0 | AG14: =COUNTIF(INDIRECT("'"&$D14&"'!"&AJ$8),"Pass") -> 0 | AH14: =COUNTIF(INDIRECT("'"&$D14&"'!"&AJ$8),"Fail") -> 0 | AI14: =COUNTIF(INDIRECT("'"&$D14&"'!"&AJ$8),"N/A") -> 0 | AJ14: =COUNTIF(INDIRECT("'"&$D14&"'!"&AJ$8),"Block") -> 0 | AK14: =SUM(AL14:AN14) -> 0 | AL14: =COUNTIF(INDIRECT("'"&$D14&"'!"&AO$8),"Pass") -> 0 | AM14: =COUNTIF(INDIRECT("'"&$D14&"'!"&AO$8),"Fail") -> 0 | AN14: =COUNTIF(INDIRECT("'"&$D14&"'!"&AO$8),"N/A") -> 0 | AO14: =COUNTIF(INDIRECT("'"&$D14&"'!"&AO$8),"Block") -> 0 | AP14: =SUM(AQ14:AS14) -> 0 | AQ14: =COUNTIF(INDIRECT("'"&$D14&"'!"&AT$8),"Pass") -> 0 | AR14: =COUNTIF(INDIRECT("'"&$D14&"'!"&AT$8),"Fail") -> 0 | AS14: =COUNTIF(INDIRECT("'"&$D14&"'!"&AT$8),"N/A") -> 0 | AT14: =COUNTIF(INDIRECT("'"&$D14&"'!"&AT$8),"Block") -> 0 | AU14: =SUM(AV14:AX14) -> 0 | AV14: =COUNTIF(INDIRECT("'"&$D14&"'!"&AY$8),"Pass") -> 0 | AW14: =COUNTIF(INDIRECT("'"&$D14&"'!"&AY$8),"Fail") -> 0 | AX14: =COUNTIF(INDIRECT("'"&$D14&"'!"&AY$8),"N/A") -> 0 | AY14: =COUNTIF(INDIRECT("'"&$D14&"'!"&AY$8),"Block") -> 0 | AZ14: =SUM(BA14:BC14) -> 0 | BA14: =COUNTIF(INDIRECT("'"&$D14&"'!"&BD$8),"Pass") -> 0 | BB14: =COUNTIF(INDIRECT("'"&$D14&"'!"&BD$8),"Fail") -> 0 | BC14: =COUNTIF(INDIRECT("'"&$D14&"'!"&BD$8),"N/A") -> 0 | BD14: =COUNTIF(INDIRECT("'"&$D14&"'!"&BD$8),"Block") -> 0
B15: 4 | C15: TC_06 | D15: Trang tổng hợp dịch vụ | E15: Trang tổng hợp dịch vụ | F15: {=COUNTIF(INDIRECT("'"&D15&"'!A:A"),C15&"*")} -> 110 | G15: =SUM(H15:J15) -> 109 | H15: =COUNTIF(INDIRECT("'"&$D15&"'!"&K$8),"Pass") -> 108 | I15: =COUNTIF(INDIRECT("'"&$D15&"'!"&K$8),"Fail") -> 0 | J15: =COUNTIF(INDIRECT("'"&$D15&"'!"&K$8),"N/A") -> 1 | K15: =COUNTIF(INDIRECT("'"&$D15&"'!"&K$8),"Block") -> 1 | L15: =SUM(M15:O15) -> 0 | M15: =COUNTIF(INDIRECT("'"&$D15&"'!"&P$8),"Pass") -> 0 | N15: =COUNTIF(INDIRECT("'"&$D15&"'!"&P$8),"Fail") -> 0 | O15: =COUNTIF(INDIRECT("'"&$D15&"'!"&P$8),"N/A") -> 0 | P15: =COUNTIF(INDIRECT("'"&$D15&"'!"&P$8),"Block") -> 0 | Q15: =SUM(R15:T15) -> 0 | R15: =COUNTIF(INDIRECT("'"&$D15&"'!"&U$8),"Pass") -> 0 | S15: =COUNTIF(INDIRECT("'"&$D15&"'!"&U$8),"Fail") -> 0 | T15: =COUNTIF(INDIRECT("'"&$D15&"'!"&U$8),"N/A") -> 0 | U15: =COUNTIF(INDIRECT("'"&$D15&"'!"&U$8),"Block") -> 0 | V15: =SUM(W15:Y15) -> 0 | W15: =COUNTIF(INDIRECT("'"&$D15&"'!"&Z$8),"Pass") -> 0 | X15: =COUNTIF(INDIRECT("'"&$D15&"'!"&Z$8),"Fail") -> 0 | Y15: =COUNTIF(INDIRECT("'"&$D15&"'!"&Z$8),"N/A") -> 0 | Z15: =COUNTIF(INDIRECT("'"&$D15&"'!"&Z$8),"Block") -> 0 | AA15: =SUM(AB15:AD15) -> 0 | AB15: =COUNTIF(INDIRECT("'"&$D15&"'!"&AE$8),"Pass") -> 0 | AC15: =COUNTIF(INDIRECT("'"&$D15&"'!"&AE$8),"Fail") -> 0 | AD15: =COUNTIF(INDIRECT("'"&$D15&"'!"&AE$8),"N/A") -> 0 | AE15: =COUNTIF(INDIRECT("'"&$D15&"'!"&AE$8),"Block") -> 0 | AF15: =SUM(AG15:AI15) -> 0 | AG15: =COUNTIF(INDIRECT("'"&$D15&"'!"&AJ$8),"Pass") -> 0 | AH15: =COUNTIF(INDIRECT("'"&$D15&"'!"&AJ$8),"Fail") -> 0 | AI15: =COUNTIF(INDIRECT("'"&$D15&"'!"&AJ$8),"N/A") -> 0 | AJ15: =COUNTIF(INDIRECT("'"&$D15&"'!"&AJ$8),"Block") -> 0 | AK15: =SUM(AL15:AN15) -> 0 | AL15: =COUNTIF(INDIRECT("'"&$D15&"'!"&AO$8),"Pass") -> 0 | AM15: =COUNTIF(INDIRECT("'"&$D15&"'!"&AO$8),"Fail") -> 0 | AN15: =COUNTIF(INDIRECT("'"&$D15&"'!"&AO$8),"N/A") -> 0 | AO15: =COUNTIF(INDIRECT("'"&$D15&"'!"&AO$8),"Block") -> 0 | AP15: =SUM(AQ15:AS15) -> 0 | AQ15: =COUNTIF(INDIRECT("'"&$D15&"'!"&AT$8),"Pass") -> 0 | AR15: =COUNTIF(INDIRECT("'"&$D15&"'!"&AT$8),"Fail") -> 0 | AS15: =COUNTIF(INDIRECT("'"&$D15&"'!"&AT$8),"N/A") -> 0 | AT15: =COUNTIF(INDIRECT("'"&$D15&"'!"&AT$8),"Block") -> 0 | AU15: =SUM(AV15:AX15) -> 0 | AV15: =COUNTIF(INDIRECT("'"&$D15&"'!"&AY$8),"Pass") -> 0 | AW15: =COUNTIF(INDIRECT("'"&$D15&"'!"&AY$8),"Fail") -> 0 | AX15: =COUNTIF(INDIRECT("'"&$D15&"'!"&AY$8),"N/A") -> 0 | AY15: =COUNTIF(INDIRECT("'"&$D15&"'!"&AY$8),"Block") -> 0 | AZ15: =SUM(BA15:BC15) -> 0 | BA15: =COUNTIF(INDIRECT("'"&$D15&"'!"&BD$8),"Pass") -> 0 | BB15: =COUNTIF(INDIRECT("'"&$D15&"'!"&BD$8),"Fail") -> 0 | BC15: =COUNTIF(INDIRECT("'"&$D15&"'!"&BD$8),"N/A") -> 0 | BD15: =COUNTIF(INDIRECT("'"&$D15&"'!"&BD$8),"Block") -> 0
B16: Total | F16: =SUM(F10:F15) -> 646 | G16: =SUM(G10:G15) -> 549 | H16: =SUM(H10:H14) -> 439 | I16: =SUM(I10:I15) -> 0 | J16: =SUM(J10:J15) -> 2 | K16: =SUM(K10:K15) -> 97 | L16: =SUM(L10) -> 0 | M16: =SUM(M10) -> 0 | N16: =SUM(N10) -> 0 | O16: =SUM(O10) -> 0 | P16: =SUM(P10) -> 0 | Q16: =SUM(Q10) -> 0 | R16: =SUM(R10) -> 0 | S16: =SUM(S10) -> 0 | ... BD16: =SUM(BD10) -> 0
B17: Rate (%) | G17: =IFERROR(G16/$F$16,0) -> 0.8498452 | H17: =IFERROR(H16/G$16,0) -> 0.7996357 | I17: =IFERROR(I16/G$16,0) -> 0 | J17: =IFERROR(J16/G$16,0) -> 0.0036429873 | K17: =IFERROR(K16/$F$16,0) -> 0.1501548 | L17: =IFERROR(L16/$F$16,0) -> 0 | M17: =IFERROR(M16/L$16,0) -> 0 | N17: =IFERROR(N16/L$16,0) -> 0 | O17: =IFERROR(O16/L$16,0) -> 0 | P17: =IFERROR(P16/$F$16,0) -> 0 | Q17: =IFERROR(Q16/$F$16,0) -> 0 | R17: =IFERROR(R16/Q$16,0) -> 0 | S17: =IFERROR(S16/Q$16,0) -> 0 | T17: =IFERROR(T16/Q$16,0) -> 0 | U17: =IFERROR(U16/$F$16,0) -> 0 | V17: =IFERROR(V16/$F$16,0) -> 0 | W17: =IFERROR(W16/V$16,0) -> 0 | X17: =IFERROR(X16/V$16,0) -> 0 | Y17: =IFERROR(Y16/V$16,0) -> 0 | Z17: =IFERROR(Z16/$F$16,0) -> 0 | AA17: =IFERROR(AA16/$F$16,0) -> 0 | AB17: =IFERROR(AB16/AA$16,0) -> 0 | AC17: =IFERROR(AC16/AA$16,0) -> 0 | AD17: =IFERROR(AD16/AA$16,0) -> 0 | AE17: =IFERROR(AE16/$F$16,0) -> 0 | AF17: =IFERROR(AF16/$F$16,0) -> 0 | AG17: =IFERROR(AG16/AF$16,0) -> 0 | AH17: =IFERROR(AH16/AF$16,0) -> 0 | AI17: =IFERROR(AI16/AF$16,0) -> 0 | AJ17: =IFERROR(AJ16/$F$16,0) -> 0 | AK17: =IFERROR(AK16/$F$16,0) -> 0 | AL17: =IFERROR(AL16/AK$16,0) -> 0 | AM17: =IFERROR(AM16/AK$16,0) -> 0 | AN17: =IFERROR(AN16/AK$16,0) -> 0 | AO17: =IFERROR(AO16/$F$16,0) -> 0 | AP17: =IFERROR(AP16/$F$16,0) -> 0 | AQ17: =IFERROR(AQ16/AP$16,0) -> 0 | AR17: =IFERROR(AR16/AP$16,0) -> 0 | AS17: =IFERROR(AS16/AP$16,0) -> 0 | AT17: =IFERROR(AT16/$F$16,0) -> 0 | AU17: =IFERROR(AU16/$F$16,0) -> 0 | AV17: =IFERROR(AV16/AU$16,0) -> 0 | AW17: =IFERROR(AW16/AU$16,0) -> 0 | AX17: =IFERROR(AX16/AU$16,0) -> 0 | AY17: =IFERROR(AY16/$F$16,0) -> 0 | AZ17: =IFERROR(AZ16/$F$16,0) -> 0 | BA17: =IFERROR(BA16/AZ$16,0) -> 0 | BB17: =IFERROR(BB16/AZ$16,0) -> 0 | BC17: =IFERROR(BC16/AZ$16,0) -> 0 | BD17: =IFERROR(BD16/$F$16,0) -> 0

Sheet Thông tin chung
A3: Mã chức năng (Function ID) | C3: TC_01
A4: Tên chức năng (Function Name) | C4: Thông tin chung
A7: Testcase ID | B7: Mức Độ Ưu Tiên (Priority) | C7: Nội Dung Test (Test Title) | D7: Điều Kiện/ Dữ Liệu Test (Pre-condition/ Test Data) | E7: Các Bước Thực Hiện (Test Steps) | F7: Kết Quả Mong Đợi (Expected Results) | G7: =Summary!G8 -> Round 1 (09/04/2026 - 15/04/2026) | M7: =Summary!L8 -> Round 2 (dd/mm/yyyy - dd/mm/yyyy) | Q7: =Summary!Q8 -> Round 3(dd/mm/yyyy - dd/mm/yyyy) | U7: =Summary!V8 -> Round 4 (dd/mm/yyyy - dd/mm/yyyy)
G8: Kết Quả Thực Hiện (Actual Result) | J8: Người Thực Hiện (Executed By) | K8: ID Bugs | L8: Ghi Chú (Remark) | M8: Kết Quả Thực Hiện (Actual Result) | N8: Người Thực Hiện (Executed By) | O8: ID Bugs | P8: Ghi Chú (Remark) | Q8: Kết Quả Thực Hiện (Actual Result) | R8: Người Thực Hiện (Executed By) | S8: ID Bugs | T8: Ghi Chú (Remark) | U8: Kết Quả Thực Hiện (Actual Result) | V8: Người Thực Hiện (Executed By) | W8: ID Bugs | X8: Ghi Chú (Remark)
A9: Các dịch vụ cần test | G9: FPL | H9: Ultra Fast | I9: HyperFast
A10: Màn hình nhập thông tin
A11: Màn hình nhập thông tin - Header
A12: =IF(E12="","",$C$3&"."&COUNTA($E$12:E12)&"") -> TC_01.1 | B12: Medium | C12: Click vào Logo FPT Telecom | D12: - Đang ở màn hình nhập thông tin đăng ký/thanh toán | E12: 1. Click vào logo FPT Telecom | F12: - Truy cập link trực tiếp: Điều hướng vào màn hình Home fpt.vn - Truy cập từ tongdaiwifi: Điều hướng về home https://staging.tongdaiwifi.vn/ | G12: Pass | H12: Pass | I12: Pass | J12: AnhDC4
A13: =IF(E13="","",$C$3&"."&COUNTA($E$12:E13)&"") -> TC_01.2 | B13: Medium | C13: Click vào icon back_ từ Home truy cập trực tiếp link | D13: - Có link đăng ký dịch vụ | E13: 1. Mở trình duyệt 2. Truy cập trực tiếp link đăng ký dịch vụ 3. Click vào icon back | F13: Điều hướng vào màn hình Home fpt.vn | G13: Pass | H13: Pass | I13: Pass | J13: AnhDC4
A14: =IF(E14="","",$C$3&"."&COUNTA($E$12:E14)&"") -> TC_01.3 | B14: Medium | C14: Click vào icon back_ từ Home tongdaiwifi.vn | D14: - Đang ở màn hình nhập thông tin đăng ký/thanh toán | E14: 1. Mở trình duyệt 2. Truy cập trang tongdaiwifi.vn 3. Click btn Đăng ký ngay 4. Click vào icon back | F14: Điều hướng về home https://staging.tongdaiwifi.vn/ | G14: Pass | H14: Pass | I14: Pass | J14: AnhDC4
A15: Màn hình nhập thông tin - Tiến trình các bước
A16: =IF(E16="","",$C$3&"."&COUNTA($E$12:E16)&"") -> TC_01.4 | B16: Medium | C16: Check màu sắc mặc định tại các bước | D16: - Đang ở màn hình nhập thông tin đăng ký/thanh toán | E16: 1. Quan sát màu sắc tại các bước tiến trình. | F16: Hiển thị đúng màu sắc mặc định tại các bước. Gồm: + Bước 1: màu xanh dương + Bước 2,3: màu xám | G16: Pass | H16: Pass | I16: Pass | J16: AnhDC4 | L16: UltraFas, HyperFast, FPL 2 bước
A17: =IF(E17="","",$C$3&"."&COUNTA($E$12:E17)&"") -> TC_01.5 | B17: Medium | C17: Click vào các bước 1,2,3 khi đang ở bước 1 | D17: - Đang ở màn hình nhập thông tin đăng ký/thanh toán - Đang ở bước 1 | E17: 1. Click vào icon của các bước 1,2,3 | F17: Không có action nào, vẫn ở màn hình hiện tại | G17: Pass | H17: Pass | I17: Pass | J17: AnhDC4
A18: =IF(E18="","",$C$3&"."&COUNTA($E$12:E18)&"") -> TC_01.6 | B18: Medium | C18: Click vào bước 1 khi đang ở bước 2 | D18: - Đang ở màn hình nhập thông tin đăng ký/thanh toán - Hiển thị tiến trình 3 bước - Đang ở bước 2 | E18: 1. Click vào icon của bước 1 | F18: Cho phép quay về bước 1 khi click vào icon bước 1 | G18: Pass | H18: Pass | I18: Pass | J18: AnhDC4
A19: Màn hình nhập thông tin - Block Sản phẩm dịch vụ đã chọn
A20: =IF(E20="","",$C$3&"."&COUNTA($E$9:E20)&"") -> TC_01.7 | B20: Medium | C20: Check load Số lượng gói dịch vụ | D20: Chọn 1 gói dịch vụ SA ở màn hình Chi tiết dịch vụ | E20: 1. Truy cập màn hình Thanh toán dịch vụ 2. Tại block Sản phẩm dịch vụ đã chọn 3. Check load Số lượng gói dịch vụ | F20: Hiển thị đúng số lượng gói dịch vụ đã chọn | G20: Pass | H20: Pass | I20: Pass | J20: AnhDC4
A21: =IF(E21="","",$C$3&"."&COUNTA($E$9:E21)&"") -> TC_01.8 | B21: Medium | C21: Check load data Gói dịch vụ | D21: Chọn 1 gói dịch vụ SA ở màn hình Chi tiết dịch vụ | E21: 1. Truy cập màn hình Thanh toán dịch vụ 2. Tại block Sản phẩm dịch vụ đã chọn 3. Check hiển thị các trường trong block Sản phẩm dịch vụ đã chọn | F21: Hệ thống hiển thị lại gói khách hàng đã chọn | G21: Pass | H21: Pass | I21: Pass | J21: AnhDC4
A22: =IF(E22="","",$C$3&"."&COUNTA($E$9:E22)&"") -> TC_01.9 | B22: Medium | C22: Check load Chu kỳ gói dịch vụ | D22: Chọn 1 gói dịch vụ SA ở màn hình Chi tiết dịch vụ | E22: 1. Truy cập màn hình Thanh toán dịch vụ 2. Tại block Sản phẩm dịch vụ đã chọn 3. Check load Chu kỳ gói dịch vụ | F22: Hệ thống hiển thị đúng chu kỳ đã chọn, ví dụ: 3 tháng, 6 tháng, 12 tháng. | G22: Pass | H22: Pass | I22: Pass | J22: AnhDC4
A23: =IF(E23="","",$C$3&"."&COUNTA($E$9:E23)&"") -> TC_01.10 | B23: Medium | C23: Check load Giá gói dịch vụ | D23: Chọn 1 gói dịch vụ SA ở màn hình Chi tiết dịch vụ | E23: 1. Truy cập màn hình Thanh toán dịch vụ 2. Tại block Sản phẩm dịch vụ đã chọn 3. Check load Giá gói dịch vụ | F23: Hệ thống hiển thị giá của gói đã chọn. Nếu có ưu đãi, hệ thống hiển thị giá sau ưu đãi. | G23: Pass | H23: Pass | I23: Pass | J23: AnhDC4 | L23: không hiển thị giá ưu đãi
A24: =IF(E24="","",$C$3&"."&COUNTA($E$9:E24)&"") -> TC_01.11 | B24: Medium | C24: Check load icon Gói dịch vụ | D24: Chọn 1 gói dịch vụ SA ở màn hình Chi tiết dịch vụ | E24: 1. Truy cập màn hình Thanh toán dịch vụ 2. Tại block Sản phẩm dịch vụ đã chọn 3. Check icon Gói dịch vụ | F24: Hiển thị đúng hình ảnh theo config Product Hub | G24: Pass | H24: Pass | I24: Pass | J24: AnhDC4
A25: Màn hình nhập thông tin - Block Thông tin Cá nhân
B26: Họ Tên (NET, ComBo Net)
B27: Medium | C27: Check khung viền màu xanh khi click chuột vào các trường Họ tên | D27: - Đang ở màn hình nhập thông tin đăng ký/thanh toán - Đang đăng ký dịch vụ NET/Combo net | E27: 1. Click vào trường Họ tên 2. Check hiển thị viền xanh | F27: Hiển thị viền màu xanh của trường | G27: none | H27: none | I27: none | K27: UltraFast/SA/HyperFast không có trường Họ tên
B28: Medium | C28: Check btn x trong trường Họ tên | D28: - Đang ở màn hình nhập thông tin đăng ký/thanh toán - Đang đăng ký dịch vụ NET/Combo net | E28: 1. Nhập 1 ký tự bất kỳ tại trường Họ tên 2. Check hiển thị icon x | F28: Hiển thị icon X khi nhập ký tự bất kỳ | G28: none | H28: none | I28: none | K28: UltraFast/SA/HyperFast không có trường Họ tên
B29: Medium | C29: Click btn x trong trường Họ tên | D29: - Đang ở màn hình nhập thông tin đăng ký/thanh toán - Đang đăng ký dịch vụ NET/Combo net | E29: 1. Nhập 1 ký tự bất kỳ tại trường Họ tên 2. Click icon x | F29: Xóa toàn bộ kí tự trong trường Họ tên và ẩn icon X | G29: none | H29: none | I29: none | K29: UltraFast/SA/HyperFast không có trường Họ tên
B30: Medium | C30: Check trường Họ tên để trống | D30: - Đang ở màn hình nhập thông tin đăng ký/thanh toán - Đang đăng ký dịch vụ NET/Combo net | E30: 1. Click vào trường Họ tên và không nhập data 2. Click ra ngoài trường Họ tên | F30: Border đỏ trường họ tên và thông báo " Vui lòng nhập họ và tên." | G30: none | H30: none | I30: none | K30: UltraFast/SA/HyperFast không có trường Họ tên
B31: Medium | C31: Check trường Họ tên nhập khoảng trắng | D31: - Đang ở màn hình nhập thông tin đăng ký/thanh toán - Đang đăng ký dịch vụ NET/Combo net | E31: 1. Click vào trường Họ tên 2. Nhập khoảng trắng 3. Click ra ngoài trường Họ tên | F31: Border đỏ trường họ tên và thông báo " Vui lòng nhập họ và tên." | G31: none | H31: none | I31: none | K31: UltraFast/SA/HyperFast không có trường Họ tên
B32: Medium | C32: Check nhập Họ tên có khoảng trắng đầu cuối | D32: - Đang ở màn hình nhập thông tin đăng ký/thanh toán - Đang đăng ký dịch vụ NET/Combo net | E32: 1. Nhập Họ tên có khoảng trắng đầu cuối 2. Nhập các trường bắt buộc khác 3. Btn Tiếp tục | F32: Cho phép qua màn hình tiếp theo không báo lỗi (khi submit sẽ trim khoảng trắng đi) | G32: none | H32: none | I32: none | K32: UltraFast/SA/HyperFast không có trường Họ tên
B33: Medium | C33: Check nhập hoặc copy-paste Họ tên có ký tự đặc biệt', số | D33: - Đang ở màn hình nhập thông tin đăng ký/thanh toán - Đang đăng ký dịch vụ NET/Combo net | E33: 1. Nhập/copy-paste họ tên có ký tự đặc biệt 2. Nhập các trường bắt buộc khác 3. Btn Tiếp tục | F33: Hiển thị thông báo "Họ tên không hợp lệ" * chỉ được nhận chữ + khoảng trắng | G33: none | H33: none | I33: none | K33: UltraFast/SA/HyperFast không có trường Họ tên
B34: Medium | C34: Check nhập/copy-paste Họ tên > 100 ký tự | D34: - Đang ở màn hình nhập thông tin đăng ký/thanh toán - Đang đăng ký dịch vụ NET/Combo net | E34: 1. Nhập/copy-paste Họ tên > 100 ký tự | F34: Chỉ cho phép nhập và hiển thị 100 ký tự | G34: none | H34: none | I34: none | K34: UltraFast/SA/HyperFast không có trường Họ tên
B35: Số điện thoại (Tất cả dịch vụ)
A36: =IF(E36="","",$C$3&"."&COUNTA($E$9:E36)&"") -> TC_01.20 | B36: Medium | C36: Check btn x trong trường Số điện thoại | D36: - Đang ở màn hình nhập thông tin đăng ký/thanh toán - Đang đăng ký dịch vụ bất kỳ | E36: 1. Nhập 1 số bất kỳ tại trường Số điện thoại 2. Check hiển thị icon x | F36: Hiển thị icon X khi nhập ký tự bất kỳ | G36: Pass | H36: Pass | I36: Pass | J36: AnhDC4
A37: =IF(E37="","",$C$3&"."&COUNTA($E$12:E37)&"") -> TC_01.21 | B37: Medium | C37: Click btn x trong trường số điện thoại | D37: - Đang ở màn hình nhập thông tin đăng ký/thanh toán - Đang đăng ký dịch vụ bất kỳ | E37: 1. Nhập số bất kỳ tại trường Số điện thoại 2. Click icon x | F37: Xóa toàn bộ kí tự trong trường Số điện thoại và ẩn icon X | G37: Pass | H37: Pass | I37: Pass | J37: AnhDC4
A38: =IF(E38="","",$C$3&"."&COUNTA($E$12:E38)&"") -> TC_01.22 | B38: Medium | C38: Check trường Số điện thoại để trống | D38: - Đang ở màn hình nhập thông tin đăng ký/thanh toán - Đang đăng ký dịch vụ bất kỳ | E38: 1. Click vào trường Số điện thoại và không nhập data 2. Click ra ngoài trường Số điện thoại | F38: Border đỏ trường số điện thoại và thông báo "Vui lòng nhập số điện thoại." | G38: Pass | H38: Pass | I38: Pass | J38: AnhDC4
A39: =IF(E39="","",$C$3&"."&COUNTA($E$12:E39)&"") -> TC_01.23 | B39: Medium | C39: Check nhập hoặc copy-paste Số điện thoại có chứa ký tự bất kỳ không phải là số | D39: - Đang ở màn hình nhập thông tin đăng ký/thanh toán - Đang đăng ký dịch vụ bất kỳ | E39: 1. Nhập/copy-paste Số điện thoại có ký tự không phải số | F39: Hiển thị thông báo "Số điện thoại không hợp lệ" | G39: Pass | H39: Pass | I39: Pass | J39: AnhDC4 | L39: show thông báo lỗi khi click button thanh toán
A40: =IF(E40="","",$C$3&"."&COUNTA($E$12:E40)&"") -> TC_01.24 | B40: Medium | C40: Check nhập Số điện thoại = 10 số nhưng số đầu tiên khác 0 | D40: - Đang ở màn hình nhập thông tin đăng ký/thanh toán - Đang đăng ký dịch vụ bất kỳ | E40: 1. Nhập Số điện thoại có 10 số nhưng có số đầu tiên khác 0 | F40: Hiển thị thông báo "Số điện thoại không hợp lệ" | G40: Pass | H40: Pass | I40: Pass | J40: AnhDC4
A41: =IF(E41="","",$C$3&"."&COUNTA($E$12:E41)&"") -> TC_01.25 | B41: Medium | C41: Check nhập hoặc copy-paste Số điện thoại dài hơn >10 chữ số | D41: - Đang ở màn hình nhập thông tin đăng ký/thanh toán - Đang đăng ký dịch vụ bất kỳ | E41: 1. Nhập /copy-paste Số điện thoại dài hơn >10 chữ số | F41: Chỉ hiển thị 10 chữ số, tự động cắt bỏ từ số 11 | G41: Pass | H41: Pass | I41: Pass | J41: AnhDC4
B42: Email (Hyperfast)
A43: =IF(E43="","",$C$3&"."&COUNTA($E$12:E43)&"") -> TC_01.26 | B43: Low | C43: Check placeholder tại trường Email | D43: - Đang ở màn hình nhập thông tin đăng ký/thanh toán - Đăng ký dịch vụ Hyperfast/UltraFast | E43: 1. Quan sát tại trường Email khi chưa nhập data | F43: Placeholder hiển thị "Nhập email" đúng gợi ý nhập email (VD: 'Acb@gmail.com') | G43: none | H43: Pass | I43: Pass | J43: AnhDC4 | L43: FPL ko có trường này Placeholder hiển thị "Nhập email"
A44: =IF(E44="","",$C$3&"."&COUNTA($E$12:E44)&"") -> TC_01.27 | B44: Medium | C44: Check btn x trong trường Email | D44: - Đang ở màn hình nhập thông tin đăng ký/thanh toán - Đăng ký dịch vụ Hyperfast/UltraFast | E44: 1. Nhập 1 ký tự bất kỳ tại trường Email 2. Check hiển thị icon x | F44: Hiển thị icon X khi nhập ký tự bất kỳ | G44: none | H44: Pass | I44: Pass | J44: AnhDC4
...

Sheet FPL SA
A3: Mã chức năng (Function ID) | C3: TC_02
A4: Tên chức năng (Function Name) | C4: FPL SA
A7: Testcase ID | B7: Mức Độ Ưu Tiên (Priority) | C7: Nội Dung Test (Test Title) | D7: Điều Kiện/ Dữ Liệu Test (Pre-condition/ Test Data) | E7: Các Bước Thực Hiện (Test Steps) | F7: Kết Quả Mong Đợi (Expected Results) | G7: =Summary!G8 -> Round 1 (09/04/2026 - 15/04/2026) | K7: =Summary!L8 -> Round 2 (dd/mm/yyyy - dd/mm/yyyy) | O7: =Summary!Q8 -> Round 3(dd/mm/yyyy - dd/mm/yyyy) | S7: =Summary!V8 -> Round 4 (dd/mm/yyyy - dd/mm/yyyy)
G8: Kết Quả Thực Hiện (Actual Result) | H8: Người Thực Hiện (Executed By) | I8: ID Bugs | J8: Ghi Chú (Remark) | K8: Kết Quả Thực Hiện (Actual Result) | L8: Người Thực Hiện (Executed By) | M8: ID Bugs | N8: Ghi Chú (Remark) | O8: Kết Quả Thực Hiện (Actual Result) | P8: Người Thực Hiện (Executed By) | Q8: ID Bugs | R8: Ghi Chú (Remark) | S8: Kết Quả Thực Hiện (Actual Result) | T8: Người Thực Hiện (Executed By) | U8: ID Bugs | V8: Ghi Chú (Remark)
A9: Điều hướng màn hình
A10: =IF(E10="","",$C$3&"."&COUNTA($E$9:E10)&"") -> TC_02.1 | B10: High | C10: Check điều hướng vào màn hình đăng ký dịch vụ FPL SA + verify URL đúng dịch vụ | E10: 1. Truy cập home page hoặc Landing page: 2. Click chọn gói dịch vụ FPL SA bất kỳ 3. Click btn Đăng ký | F10: Điều hướng vào trang đăng ký và đúng URL dịch vụ | G10: Pass | H10: AnhDC4
A11: =IF(E11="","",$C$3&"."&COUNTA($E$9:E11)&"") -> TC_02.2 | B11: High | C11: Check truy cập trực tiếp bằng đường dẫn | E11: 1. Truy cập trực tiếp bằng đường dẫn url:https://staging.fpt.vn/checkout/register/<goi fplSA>?salechannelcode=tongdaiwifi | F11: Điều hướng vào trang đăng ký của dịch vụ đã chọn | G11: Pass | H11: AnhDC4
A12: =IF(E12="","",$C$3&"."&COUNTA($E$9:E12)&"") -> TC_02.3 | B12: Medium | C12: Check GUI màn hình trang đăng ký dịch vụ FPL SA | E12: 1. Truy cập home page hoặc Landing page: 2. Click chọn gói dịch vụ FPL SA bất kỳ 3. Click btn Đăng ký 4. Check GUI màn hình trang đăng ký dịch vụ FPL SA | F12: Hiển thị UI gồm: - Thanh tiến trình 2 bước: Thanh toán - Hoàn tất đơn hàng - Block Sản phẩm dịch vụ đã chọn - Block Thông tin cá nhân - Block Hình thức kích hoạt dịch vụ - Block Thông tin địa chỉ - Block Phương thức thanh toán - Block Thông tin khách hàng - Block Thông tin thanh toán | G12: Pass | H12: AnhDC4
A13: Màn hình Thông tin thanh toán
A14: =IF(C14="","",$C$3&"."&COUNTA($C$9:C14)&"") | B14: Block Sản phẩm dịch vụ đã chọn
A15: =IF(E15="","",$C$3&"."&COUNTA($E$9:E15)&"") -> TC_02.4 | B15: Medium | C15: Check hiển thị các trường trong block Sản phẩm dịch vụ đã chọn | D15: Chọn 1 gói dịch vụ SA ở màn hình Chi tiết dịch vụ | E15: 1. Truy cập màn hình Thanh toán dịch vụ FPL SA 2.Check hiển thị các trường trong block Sản phẩm dịch vụ đã chọn | F15: Block hiển thị thông tin gồm: Title Sản phẩm dịch vụ đã chọn (Số lượng) - Icon Gói dịch vụ - Tên gói dịch vụ - Chu kỳ gói dịch vụ - Giá tiền * refer sheet: Thông tin chung | G15: Pass | H15: AnhDC4
A16: =IF(C16="","",$C$3&"."&COUNTA($C$9:C16)&"") | B16: Block Thông tin cá nhân
A17: =IF(E17="","",$C$3&"."&COUNTA($E$9:E17)&"") -> TC_02.5 | B17: Medium | C17: Check hiển thị các trường trong block Thông tin cá nhân | E17: 1. Truy cập màn hình Thanh toán dịch vụ FPL SA 2. Check UI block Thông tin cá nhân | F17: Block hiển thị trường: - Số điện thoại (*) Ref: sheet Thông tin chung | G17: Pass | H17: AnhDC4
A18: =IF(E18="","",$C$3&"."&COUNTA($E$9:E18)&"") -> TC_02.6 | B18: High | C18: Check nhập Số điện thoại là SDT đã đăng ký dịch vụ FPT Play | D18: Số điện thoại nhập là số đã đăng ký dịch vụ FPT Play | E18: 1. Truy cập màn hình Thanh toán dịch vụ FPL SA 2. Tại block Thông tin cá nhân 3. Nhập Số điện thoại là SDT đã đăng ký dịch vụ FPT Play 4. Nhập đầy đủ các trường bắt buộc khác 5. Click button Thanh toán | F18: Show thông báo lỗi Số điện thoại đã đăng ký dịch vụ FPT Play | G18: Pass | H18: AnhDC4
A19: =IF(E19="","",$C$3&"."&COUNTA($E$9:E19)&"") -> TC_02.7 | B19: High | C19: Check nhập Số điện thoại là SDT chưa đăng ký dịch vụ FPT Play | D19: Số điện thoại nhập là số chưa đăng ký dịch vụ FPT Play | E19: 1. Truy cập màn hình Thanh toán dịch vụ FPL SA 2. Tại block Thông tin cá nhân 3. Nhập Số điện thoại là SDT chưa đăng ký dịch vụ FPT Play 4. Nhập đầy đủ các trường bắt buộc khác 5. Click button Thanh toán | F19: Không show thông báo lỗi ở trường Số điện thoại | G19: Pass | H19: AnhDC4
A20: =IF(C20="","",$C$3&"."&COUNTA($C$9:C20)&"") | B20: Block Hình thức kích hoạt dịch vụ
A21: =IF(E21="","",$C$3&"."&COUNTA($E$9:E21)&"") -> TC_02.8 | B21: Medium | C21: Check hiển thị các trường trong Block Hình thức kích hoạt dịch vụ | E21: 1. Truy cập màn hình Thanh toán dịch vụ FPL SA 2. Check UI Block Hình thức kích hoạt dịch vụ | F21: Block hiển thị gồm: - Radio button Kích hoạt tự động (kèm icon ⓘ) - Mặc định tick chọn - Radio button Khách hàng tự kích hoạt (kèm icon ⓘ) - Checkbox Tôi muốn nhận hóa đơn - Mặc định uncheck | G21: Pass | H21: GiangDC2
A22: =IF(E22="","",$C$3&"."&COUNTA($E$9:E22)&"") -> TC_02.9 | B22: Medium | C22: Check hover icon ⓘ ở Radio button Kích hoạt tự động | E22: 1. Truy cập màn hình Thanh toán FPL SA 2. Check hover icon ⓘ ở Radio button Kích hoạt tự động | F22: Hiển thị nội dung " Tài khoản FPT Play sẽ được kích hoạt ngay sau khi thanh toán thành công. Vui lòng đăng nhập trên FPTplay.vn hoặc ứng dụng FPT Play (Mobile/Smart TV) để sử dụng dịch vụ. " | G22: Pass | H22: GiangDC2
A23: =IF(E23="","",$C$3&"."&COUNTA($E$9:E23)&"") -> TC_02.10 | B23: Medium | C23: Check hover icon ⓘ ở Radio button Khách hàng tự kích hoạt | E23: 1. Truy cập màn hình Thanh toán FPL SA 2. Check hover icon ⓘ ở Radio button Khách hàng tự kích hoạt | F23: Hiển thị nội dung " Mã kích hoạt FPT Play sẽ được gửi qua SMS sau khi thanh toán thành công. Vui lòng nhập mã và kích hoạt dịch vụ trên FPTplay.vn hoặc ứng dụng FPT Play (Mobile/Smart TV) khi sử dụng. " | G23: Pass | H23: GiangDC2
A24: =IF(E24="","",$C$3&"."&COUNTA($E$9:E24)&"") -> TC_02.11 | B24: Medium | C24: Check chọn 'Kích hoạt tự động' ghi nhận đúng vào đơn hàng | E24: 1. Truy cập màn hình Thanh toán FPL SA 2. Chọn radio 'Kích hoạt tự động' 3. Điền đầy đủ thông tin 4. Click 'Thanh toán' 5. Check thông tin tại bước Hoàn tất | F24: Hình thức 'Kích hoạt tự động' được ghi nhận và hiển thị đúng trên đơn hàng | G24: Pass | H24: GiangDC2
A25: =IF(E25="","",$C$3&"."&COUNTA($E$9:E25)&"") -> TC_02.12 | B25: Medium | C25: Check chọn 'Khách hàng tự kích hoạt' ghi nhận đúng vào đơn hàng | E25: 1. Truy cập màn hình Thanh toán FPL SA 2. Chọn radio 'Khách hàng tự kích hoạt' 3. Điền đầy đủ thông tin 4. Click 'Thanh toán' 5. Check thông tin tại bước Hoàn tất | F25: Hình thức 'Khách hàng tự kích hoạt' được ghi nhận đúng trên đơn hàng | G25: Pass | H25: GiangDC2
A26: =IF(E26="","",$C$3&"."&COUNTA($E$9:E26)&"") -> TC_02.13 | B26: Medium | C26: Check chỉ 1 radio hình thức kích hoạt được chọn tại một thời điểm | E26: 1. Truy cập màn hình Thanh toán FPL SA 2. Chọn 'Kích hoạt tự động' 3. Chọn 'Khách hàng tự kích hoạt' 4. Check trạng thái 2 radio | F26: Chỉ 1 radio được chọn — radio trước tự bỏ chọn Hoạt động đúng như radio button group | G26: Pass | H26: GiangDC2
A27: =IF(E27="","",$C$3&"."&COUNTA($E$16:E27)&"") | B27: Block Thông tin khách hàng
A28: =IF(E28="","",$C$3&"."&COUNTA($E$9:E28)&"") -> TC_02.14 | B28: Medium | C28: Check hiển thị tại Block Thông tin khách hàng | E28: 1. Truy cập màn hình Thanh toán FPL SA 2. Check hiển thị tại Block Thông tin khách hàng | F28: Hiển thị các trường thông tin gồm: - Số điện thoại - Địa chỉ (nếu có nhập địa chỉ) - icon collapse (mặc định) | G28: Pass | H28: AnhDC4 | I28: https://foxproject.atlassian.net/browse/EP-937 | J28: đã fix trong round
A29: =IF(E29="","",$C$3&"."&COUNTA($E$9:E29)&"") | B29: Block Thông tin thanh toán
A30: =IF(E30="","",$C$3&"."&COUNTA($E$9:E30)&"") -> TC_02.15 | B30: Medium | C30: Check mặc định hiển thị tại block Thông tin thanh toán | E30: 1. Truy cập màn hình Thanh toán FPL SA 2. Check hiển thị tại block Thông tin thanh toán | F30: Hiển thị các thông tin gồm + Tên gói - chu kỳ - giá tiền + Textbox Nhập ưu đãi - hyperlink Chọn ưu đãi - Button Áp dụng + Cần thanh toán - Giá tiền + Button Thanh toán + icon collapse (mặc định) + Text (Bằng việc nhấn vào nút Thanh toán bạn đã đồng ý với các <linktext> điều khoản của FPT Telecom | G30: Pass | H30: GiangDC2
A31: Màn hình Hoàn tất đơn hàng
A32: =IF(E32="","",$C$3&"."&COUNTA($E$9:E32)&"") -> TC_02.16 | B32: High | C32: Check giao diện bước Hoàn tất đơn hàng_Chưa thanh toán | D32: - Thanh toán COD | E32: 1. Tại bước Hoàn tất đơn hàng 2. Check giao diện bước hoàn tất | F32: Hiển thị giao diện hoàn tất đơn hàng như sau: - Logo FPT Telecom - Các bước: Đăng ký |Thanh toán|Hoàn tất màu xanh lá - Label: Hoàn tất đơn hàng Chưa thanh toán Đơn hàng đã đăng ký thành công. Kỹ thuật viên FPT Telecom sẽ liên hệ triển khai dịch vụ trong 8h - 12h. Mọi thắc mắc, vui lòng liên hệ 19006600 để được giải đáp, Xin cám ơn. - Button Xác nhận - Block Thông tin đơn hàng (ref: sheet Thông tin chung) | G32: Block | H32: GiangDC2 | J32: FPL ko có COD
A33: =IF(E33="","",$C$3&"."&COUNTA($E$9:E33)&"") -> TC_02.17 | B33: High | C33: Check giao diện bước Hoàn tất đơn hàng_Đã thanh toán | D33: - Thanh toán khác COD | E33: 1. Tại bước Hoàn tất đơn hàng 2. Check giao diện bước hoàn tất | F33: Hiển thị giao diện hoàn tất đơn hàng như sau: - Logo FPT Telecom - Các bước: Đăng ký |Thanh toán|Hoàn tất màu xanh lá - Label: Hoàn tất đơn hàng Thanh toán thành công Đăng ký thành công! Cảm ơn quý khách đã đăng ký sử dụng dịch vụ của FPT Telecom. Mọi thắc mắc, vui lòng liên hệ 1900 6600 để được giải đáp. Xin cảm ơn! - Button Xác nhận - Block Thông tin đơn hàng(ref: sheet Thông tin chung) | G33: N/A | H33: GiangDC2 | I33: https://foxproject.atlassian.net/browse/EP-975 | J33: bug won't fix
A34: =IF(E34="","",$C$3&"."&COUNTA($E$9:E34)&"") -> TC_02.18 | B34: High | C34: Check nhận SMS qua Số điện thoại đã đăng ký dịch vụ | D34: - Đã thanh toán đơn hàng - Tick chọn hình thức kích hoạt = Khách hàng tự kích hoạt | E34: 1. Tại bước Hoàn tất đơn hàng 2. Check nhận SMS qua Số điện thoại đã đăng ký dịch vụ | F34: Hệ thống gửi SMS bao gồm mã Code về Số điện thoại đã đăng ký dịch vụ | G34: Block | H34: GiangDC2 | J34: Chưa test được do stag FPL update hạ tầng
A35: =IF(E35="","",$C$3&"."&COUNTA($E$9:E35)&"") -> TC_02.19 | B35: High | C35: Check dịch vụ được tự động kích hoạt thành công | D35: - Đã thanh toán đơn hàng - Tick chọn hình thức kích hoạt = Kích hoạt tự động | E35: 1. Tại bước Hoàn tất đơn hàng 2. Check dịch vụ được tự động kích hoạt thành công | F35: Hệ thống sẽ kích hoạt dịch vụ cho SĐT KH đã nhập ở thông tin cá nhân | G35: Block | H35: GiangDC2 | J35: Chưa test được do stag FPL update hạ tầng
A36: =IF(E36="","",$C$3&"."&COUNTA($E$9:E36)&"") -> TC_02.20 | B36: High | C36: Check show thông báo lỗi khi tự động kích hoạt dịch vụ thất bại | D36: - Đã thanh toán đơn hàng - Tick chọn hình thức kích hoạt = Kích hoạt tự động - Kích hoạt dịch vụ thất bại sau thanh toán | E36: 1. Tại bước Hoàn tất đơn hàng 2. Check dịch vụ được tự động kích hoạt thất bại | F36: - Hệ thống show thông báo "Có lỗi trong quá trình kích hoạt dịch vụ, vui lòng thử lại sau hoặc liên hệ tổng đài 19006600" - Không chuyển sang trạng thái hoàn tất dịch vụ | G36: Block | H36: GiangDC2 | J36: Chưa test được do stag FPL update hạ tầng
A37: =IF(E37="","",$C$3&"."&COUNTA($E$9:E37)&"") -> TC_02.21 | B37: High | C37: Check show thông báo lỗi khi tự động kích hoạt dịch vụ timeout | D37: - Đã thanh toán đơn hàng - Tick chọn hình thức kích hoạt = Kích hoạt tự động - Kích hoạt dịch vụ thất bại sau thanh toán | E37: 1. Tại bước Hoàn tất đơn hàng 2. Check show thông báo lỗi khi tự động kích hoạt dịch vụ timeout | F37: - Hệ thống show thông báo "Quá trình xử lý mất nhiều thời gian, vui lòng thử lại sau" - Cho phép khách hàng đóng lại để tiếp tục | G37: Block | H37: GiangDC2 | J37: Chưa test được do stag FPL update hạ tầng
A38: =IF(E38="","",$C$3&"."&COUNTA($E$9:E38)&"") -> TC_02.22 | B38: High | C38: Click btn Xác nhận | D38: - Thanh toán thành công | E38: 1. Tại bước Hoàn tất đơn hàng 2. Click btn Xác nhận | F38: Quay về màn hình home page nếu trực tiếp link Quay về tongdaiwifi nếu đi từ tongdaiwifi | G38: Pass | H38: GiangDC2

Sheet Ultra Fast
A3: Mã chức năng (Function ID) | C3: TC_03
A4: Tên chức năng (Function Name) | C4: Ultra Fast
A7: Testcase ID | B7: Mức Độ Ưu Tiên (Priority) | C7: Nội Dung Test (Test Title) | D7: Điều Kiện/ Dữ Liệu Test (Pre-condition/ Test Data) | E7: Các Bước Thực Hiện (Test Steps) | F7: Kết Quả Mong Đợi (Expected Results) | G7: =Summary!G8 -> Round 1 (09/04/2026 - 15/04/2026) | K7: =Summary!L8 -> Round 2 (dd/mm/yyyy - dd/mm/yyyy) | O7: =Summary!Q8 -> Round 3(dd/mm/yyyy - dd/mm/yyyy) | S7: =Summary!V8 -> Round 4 (dd/mm/yyyy - dd/mm/yyyy)
G8: Kết Quả Thực Hiện (Actual Result) | H8: Người Thực Hiện (Executed By) | I8: ID Bugs | J8: Ghi Chú (Remark) | K8: Kết Quả Thực Hiện (Actual Result) | L8: Người Thực Hiện (Executed By) | M8: ID Bugs | N8: Ghi Chú (Remark) | O8: Kết Quả Thực Hiện (Actual Result) | P8: Người Thực Hiện (Executed By) | Q8: ID Bugs | R8: Ghi Chú (Remark) | S8: Kết Quả Thực Hiện (Actual Result) | T8: Người Thực Hiện (Executed By) | U8: ID Bugs | V8: Ghi Chú (Remark)
A9: Điều hướng màn hình
A10: =IF(E10="","",$C$3&"."&COUNTA($E$9:E10)&"") -> TC_03.1 | B10: High | C10: Check điều hướng vào màn hình đăng ký dịch vụ Ultra Fast + verify URL đúng dịch vụ | E10: 1. Truy cập home page hoặc Landing page: 2. Click chọn gói dịch vụ Ultra Fast bất kỳ 3. Click btn Đăng ký | F10: Điều hướng vào trang đăng ký và đúng URL dịch vụ | G10: Pass | H10: AnhDC4
A11: =IF(E11="","",$C$3&"."&COUNTA($E$9:E11)&"") -> TC_03.2 | B11: High | C11: Check truy cập trực tiếp bằng đường dẫn | E11: 1. Truy cập trực tiếp bằng đường dẫn url:https://staging.fpt.vn/checkout/register/<goi Ultralfast>?salechannelcode=tongdaiwifi | F11: Điều hướng vào trang đăng ký của dịch vụ đã chọn | G11: Pass | H11: AnhDC4
A12: =IF(E12="","",$C$3&"."&COUNTA($E$9:E12)&"") -> TC_03.3 | B12: Medium | C12: Check GUI màn hình trang đăng ký dịch vụ Ultra Fast | E12: 1. Truy cập home page hoặc Landing page: 2. Click chọn gói dịch vụ Ultra Fast bất kỳ 3. Click btn Đăng ký 4. Check GUI màn hình trang đăng ký dịch vụ Ultra Fast | F12: Hiển thị UI gồm: - Thanh tiến trình 2 bước: Thanh toán - Hoàn tất đơn hàng - Block Sản phẩm dịch vụ đã chọn - Block Thông tin cá nhân - Block Địa chỉ lắp đặt - Block Phương thức thanh toán - Block Thông tin khách hàng - Block Thông tin thanh toán | G12: Pass | H12: AnhDC4
A13: Màn hình Thông tin thanh toán
A14: =IF(C14="","",$C$3&"."&COUNTA($C$9:C14)&"") | B14: Block Sản phẩm dịch vụ đã chọn
A15: =IF(E15="","",$C$3&"."&COUNTA($E$9:E15)&"") -> TC_03.4 | B15: Medium | C15: Check hiển thị các trường trong block Sản phẩm dịch vụ đã chọn | D15: Chọn 1 gói dịch vụ Ultra Fast ở màn hình Chi tiết dịch vụ | E15: 1. Truy cập màn hình Thanh toán dịch vụ Ultra Fast 2.Check hiển thị các trường trong block Sản phẩm dịch vụ đã chọn | F15: Block hiển thị thông tin gồm: Title Sản phẩm dịch vụ đã chọn (Số lượng) - Icon Gói dịch vụ - Tên gói dịch vụ - Chu kỳ gói dịch vụ - Giá tiền Ref: sheet Thông tin chung | G15: Pass | H15: AnhDC4
A16: =IF(C16="","",$C$3&"."&COUNTA($C$9:C16)&"") | B16: Block Thông tin cá nhân
A17: =IF(E17="","",$C$3&"."&COUNTA($E$9:E17)&"") -> TC_03.5 | B17: Medium | C17: Check hiển thị các trường trong block Thông tin cá nhân | E17: 1. Truy cập màn hình Thanh toán dịch vụ Ultra Fast 2. Check UI block Thông tin cá nhân | F17: Block hiển thị 2 trường: - Số điện thoại (*) - Checkbox Tôi muốn nhận hóa đơn | G17: Pass | H17: AnhDC4 | I17: https://foxproject.atlassian.net/browse/EP-890 | J17: đã fix trong round
A18: =IF(E18="","",$C$3&"."&COUNTA($E$9:E18)&"") -> TC_03.6 | B18: Medium | C18: Check tick chọn checkbox Tôi muốn nhận hóa đơn | E18: 1. Truy cập màn hình Thanh toán dịch vụ Ultra Fast 2. Check tick chọn checkbox Tôi muốn nhận hóa đơn | F18: Hiển thị block Địa chỉ lắp đặt Hiện thị thêm textbox Email cạnh SĐT | G18: Pass | H18: AnhDC4 | I18: https://foxproject.atlassian.net/browse/EP-890 | J18: đã fix trong round
A19: =IF(E19="","",$C$3&"."&COUNTA($E$16:E19)&"") | B19: Block Thông tin khách hàng
A20: =IF(E20="","",$C$3&"."&COUNTA($E$9:E20)&"") -> TC_03.7 | B20: Medium | C20: Check hiển thị tại Block Thông tin khách hàng | E20: 1. Truy cập màn hình Thanh toán dịch vụ Ultra Fast 2. Check hiển thị tại Block Thông tin khách hàng | F20: Hiển thị các trường thông tin gồm: - Số điện thoại - Email(hiện nếu có chọnTôi muốn nhận hóa đơn) - Địa chỉ(hiện nếu có chọn Tôi muốn nhận hóa đơn) - icon collapse (mặc định) Ref: sheet Thông tin chung | G20: Pass | H20: AnhDC4 | I20: https://foxproject.atlassian.net/browse/EP-890 | J20: đã fix trong round
A21: =IF(E21="","",$C$3&"."&COUNTA($E$9:E21)&"") | B21: Thông tin thanh toán
A22: =IF(E22="","",$C$3&"."&COUNTA($E$9:E22)&"") -> TC_03.8 | B22: Medium | C22: Check mặc định hiển thị tại block Thông tin thanh toán | E22: 1. Truy cập màn hình Thanh toán dịch vụ Ultra Fast 2 . Check hiển thị tại block Thông tin thanh toán | F22: Hiển thị các thông tin gồm + Tên gói - 1 tháng - giá tiền + Textbox Nhập ưu đãi - hyperlink Chọn ưu đãi - Button Áp dụng + Cần thanh toán - Giá tiền + Button Thanh toán + icon collapse (mặc định) + Text (Bằng việc nhấn vào nút Thanh toán bạn đã đồng ý với các <linktext> điều khoản của FPT Telecom | G22: Pass | H22: AnhDC4
A23: Màn hình Hoàn tất đơn hàng
A24: =IF(E24="","",$C$3&"."&COUNTA($E$9:E24)&"") -> TC_03.9 | B24: High | C24: Check giao diện bước Hoàn tất đơn hàng_Chưa thanh toán | D24: - Thanh toán COD | E24: 1. Hoàn tất đơn hàng thanh toán COD 2. Check giao diện bước hoàn tất | F24: Hiển thị giao diện hoàn tất đơn hàng như sau: - Logo FPT Telecom - Các bước: Đăng ký |Thanh toán|Hoàn tất màu xanh lá - Label: Hoàn tất đơn hàng Chưa thanh toán Đăng ký thành công! Cảm ơn quý khách đã đăng ký sử dụng dịch vụ của FPT Telecom. Mọi thắc mắc, vui lòng liên hệ 1900 6600 để được giải đáp. Xin cảm ơn! - Block Thông tin đơn hàng(ref: sheet Thông tin chung) | G24: Block | H24: AnhDC4 | J24: cs hiện tại không có COD
A25: =IF(E25="","",$C$3&"."&COUNTA($E$9:E25)&"") -> TC_03.10 | B25: High | C25: Check giao diện bước Hoàn tất đơn hàng_Đã thanh toán | D25: - Thanh toán khác COD | E25: 1. Hoàn tất đơn hàng thanh toán khác COD 2. Check giao diện bước hoàn tất | F25: Hiển thị giao diện hoàn tất đơn hàng như sau: - Logo FPT Telecom - Các bước: Đăng ký |Thanh toán|Hoàn tất màu xanh lá - Label: Hoàn tất đơn hàng Thanh toán thành công Đăng ký thành công! Cảm ơn quý khách đã đăng ký sử dụng dịch vụ của FPT Telecom. Mọi thắc mắc, vui lòng liên hệ 1900 6600 để - Mã code Ultra Fast của bạn là: + Icon Ultra Fast + Mã code - Icon Sao chép + Button Kích hoạt code - Block Thông tin đơn hàng(ref: sheet Thông tin chung) | G25: Pass | H25: AnhDC4 | I25: SMS đang gửi kèm mã code | J25: sprint hiện tại chưa test được kích hoạt, đang ẩn button kích hoạt
A26: =IF(E26="","",$C$3&"."&COUNTA($E$9:E26)&"") -> TC_03.11 | B26: High | C26: Check hiển thị mã code ở màn hình Thanh toán thành công | D26: - Đã thanh toán đơn hàng | E26: 1. Tại bước Hoàn tất đơn hàng 2. Check hiển thị mã code ở màn hình Thanh toán thành công | F26: Hệ thống hiển thị mã code Ultra Fast | G26: Pass | H26: AnhDC4 | I26: https://foxproject.atlassian.net/browse/EP-910 | J26: đã fix trong round
A27: =IF(E27="","",$C$3&"."&COUNTA($E$9:E27)&"") -> TC_03.12 | B27: High | C27: Check show thông báo lỗi khi không gen được mã code | D27: - Đã thanh toán đơn hàng | E27: 1. Tại bước Hoàn tất đơn hàng 2. Check show thông báo lỗi khi không lấy được mã code | F27: Hệ thống hiển thị thông báo "Lấy mã không thành công. Liên hệ 1900 6600 để nhận hỗ trợ." Nút "Kích hoạt code" bị disable | G27: Block | H27: AnhDC4 | J27: chưa check được case này
A28: =IF(E28="","",$C$3&"."&COUNTA($E$9:E28)&"") -> TC_03.13 | B28: High | C28: Click icon Sao chép mã code Ultra Fast | D28: - Đã thanh toán đơn hàng | E28: 1. Tại bước Hoàn tất đơn hàng 2. Click icon Sao chép mã code Ultra Fast | F28: Hệ thống cho phép sao chép mã code thành công vào bộ nhớ tạm | G28: Pass | H28: AnhDC4
A29: =IF(E29="","",$C$3&"."&COUNTA($E$9:E29)&"") -> TC_03.14 | B29: High | C29: Click button Kích hoạt code khi Số điện thoại không tìm thấy hợp đồng FTEL | D29: - Đã thanh toán đơn hàng | E29: 1. Tại bước Hoàn tất đơn hàng 2. Click button Kích hoạt code khi Số điện thoại không tìm thấy hợp đồng FTEL | F29: Hệ thống show thông báo "Không tìm thấy hợp đồng. Số điện thoại đăng ký hiện chưa có hợp đồng sử dụng dịch vụ của FPT Telecom. Bấm Kích hoạt để chuyển đến màn hình kích hoạt FID." - Button Đồng ý | G29: Block | H29: AnhDC4 | J29: sprint hiện tại chưa test được kích hoạt, đang ẩn button kích hoạt
A30: =IF(E30="","",$C$3&"."&COUNTA($E$9:E30)&"") -> TC_03.15 | B30: High | C30: Click button Đồng ý ở popup Không tìm thấy hợp đồng | D30: - Đã thanh toán đơn hàng - Số điện thoại chưa có HĐ FTEL | E30: 1. Tại bước Hoàn tất đơn hàng 2. Click button Kích hoạt code khi Số điện thoại không tìm thấy hợp đồng FTEL 3. Click button Đồng ý ở popup Không tìm thấy hợp đồng | F30: Hệ thống điều hướng KH sang luồng FID. | G30: Block | H30: AnhDC4 | J30: sprint hiện tại chưa test được kích hoạt, đang ẩn button kích hoạt
A31: =IF(E31="","",$C$3&"."&COUNTA($E$9:E31)&"") -> TC_03.16 | B31: High | C31: Click button Kích hoạt code khi Số điện thoại đăng ký có > 1 Hợp đồng | D31: - Đã thanh toán đơn hàng - Số điện thoại đăng ký có > 1 hợp đồng | E31: 1. Tại bước Hoàn tất đơn hàng 2. Click button Kích hoạt code khi Số điện thoại đăng ký có > 1 Hợp đồng | F31: Hệ thống hiển thị popup Danh sách hợp đồng của SDT đã đăng ký: - Title: Chọn mã hợp đồng kích hoạt Ultra Fast - Danh sách hợp đồng thuộc SDT đăng ký - Button Xác nhận - Button Quay lại | G31: Block | H31: AnhDC4 | J31: sprint hiện tại chưa test được kích hoạt, đang ẩn button kích hoạt
A32: =IF(E32="","",$C$3&"."&COUNTA($E$9:E32)&"") -> TC_03.17 | B32: High | C32: Check load danh sách Số hợp đồng thuộc số điện thoại đã đăng ký | D32: - Đã thanh toán đơn hàng - Số điện thoại đăng ký có > 1 hợp đồng | E32: 1. Tại bước Hoàn tất đơn hàng 2. Click button Kích hoạt code khi Số điện thoại đăng ký có > 1 Hợp đồng 3. Tại popup Danh sách hợp đồng của SDT đăng ký 4. Check load danh sách Số hợp đồng thuộc số điện thoại đã đăng ký | F32: Hệ thống load đúng danh sách số hợp đồng thuộc SDT đăng ký | G32: Block | H32: AnhDC4 | J32: sprint hiện tại chưa test được kích hoạt, đang ẩn button kích hoạt
A33: =IF(E33="","",$C$3&"."&COUNTA($E$9:E33)&"") -> TC_03.18 | B33: High | C33: Check chọn 1 hợp đồng trong danh sách hợp đồng | D33: - Đã thanh toán đơn hàng - Số điện thoại đăng ký có > 1 hợp đồng | E33: 1. Tại bước Hoàn tất đơn hàng 2. Click button Kích hoạt code khi Số điện thoại đăng ký có > 1 Hợp đồng 3. Tại popup Danh sách hợp đồng của SDT đăng ký 4. Check chọn 1 hợp đồng trong danh sách hợp đồng | F33: Hệ thống cho phép chọn 1 hợp đồng trong danh sách, không được chọn nhiều hơn 1 hợp đồng | G33: Block | H33: AnhDC4 | J33: sprint hiện tại chưa test được kích hoạt, đang ẩn button kích hoạt
A34: =IF(E34="","",$C$3&"."&COUNTA($E$9:E34)&"") -> TC_03.19 | B34: High | C34: Click button Xác nhận khi chưa chọn hợp đồng | D34: - Đã thanh toán đơn hàng - Số điện thoại đăng ký có > 1 hợp đồng | E34: 1. Tại bước Hoàn tất đơn hàng 2. Click button Kích hoạt code khi Số điện thoại đăng ký có > 1 Hợp đồng 3. Tại popup Danh sách hợp đồng của SDT đăng ký 4. Không chọn hợp đồng 5. Click button Xác nhận | F34: Hệ thống show thông báo lỗi khi chưa chọn Số hợp đồng | G34: Block | H34: AnhDC4 | J34: sprint hiện tại chưa test được kích hoạt, đang ẩn button kích hoạt
A35: =IF(E35="","",$C$3&"."&COUNTA($E$9:E35)&"") -> TC_03.20 | B35: High | C35: Click button Xác nhận khi đã chọn hợp đồng | D35: - Đã thanh toán đơn hàng - Số điện thoại đăng ký có > 1 hợp đồng | E35: 1. Tại bước Hoàn tất đơn hàng 2. Click button Kích hoạt code khi Số điện thoại đăng ký có > 1 Hợp đồng 3. Tại popup Danh sách hợp đồng của SDT đăng ký 4. Chọn 1 hợp đồng 5. Click button Xác nhận | F35: Hê thống hiển thị popup show thông báo "Kích hoạt thành công. Dịch vụ Ultra Fast - {Số tháng} đã được kích hoạt cho hợp đồng {Mã HĐ}. Thời gian sử dụng từ {Ngày} đến {Ngày}" - Button Đóng đóng popup - Icon X * Thời gian sử dụng tương ứng với Gói dich vụ đã đăng ký * Mã HD: Số hợp đồng đã chọn Format: dd/mm/yyyy | G35: Block | H35: AnhDC4 | J35: sprint hiện tại chưa test được kích hoạt, đang ẩn button kích hoạt
